<robot name = "robot">
    <link name="Cube0">
        <inertial>
            <origin xyz="0.0 0.0 3" rpy="0 0 0"/>
            <mass value="1" />
            <inertia ixx="100" ixy="0" ixz="0" iyy="100" iyz="0" izz="100" />
        </inertial>
        <visual>
            <origin xyz="0.0 0.0 3" rpy="0 0 0"/>
            <geometry>
                <box size="1.2682994739163163 1.4233887778146372 0.8498320258026599" />
            </geometry>
            <material name="Green">
                <color rgba="0.1 0.9 0.1 0.9"/>
            </material>
        </visual>
        <collision>
            <origin xyz="0.0 0.0 3" rpy="0 0 0"/>
            <geometry>
                <box size="1.2682994739163163 1.4233887778146372 0.8498320258026599" />
            </geometry>
        </collision>
    </link>
    <joint name="Cube0_Cube1" type="revolute">
       <parent link="Cube0"/>
       <child  link="Cube1"/>
       <origin rpy="0 0 0" xyz="0.0 -0.7116943889073186 3" />
     <axis xyz="0 1 0"/>
       <limit effort="0.0" lower="-3.14159" upper="3.14159" velocity="0.0"/>
    </joint>
    <link name="Cube1">
        <inertial>
            <origin xyz="0.0 -0.4845105351546938 0.0" rpy="0 0 0"/>
            <mass value="1" />
            <inertia ixx="100" ixy="0" ixz="0" iyy="100" iyz="0" izz="100" />
        </inertial>
        <visual>
            <origin xyz="0.0 -0.4845105351546938 0.0" rpy="0 0 0"/>
            <geometry>
                <box size="0.5559921551143994 0.9690210703093876 0.34377714203353293" />
            </geometry>
            <material name="Blue">
                <color rgba="0.1 0.2 0.9 0.9"/>
            </material>
        </visual>
        <collision>
            <origin xyz="0.0 -0.4845105351546938 0.0" rpy="0 0 0"/>
            <geometry>
                <box size="0.5559921551143994 0.9690210703093876 0.34377714203353293" />
            </geometry>
        </collision>
    </link>
    <joint name="Cube1_Cube2" type="revolute">
       <parent link="Cube1"/>
       <child  link="Cube2"/>
       <origin rpy="0 0 0" xyz="0.0 -0.9690210703093876 0.0" />
     <axis xyz="0 1 0"/>
       <limit effort="0.0" lower="-3.14159" upper="3.14159" velocity="0.0"/>
    </joint>
    <link name="Cube2">
        <inertial>
            <origin xyz="0.0 -0.20985924358015787 0.0" rpy="0 0 0"/>
            <mass value="1" />
            <inertia ixx="100" ixy="0" ixz="0" iyy="100" iyz="0" izz="100" />
        </inertial>
        <visual>
            <origin xyz="0.0 -0.20985924358015787 0.0" rpy="0 0 0"/>
            <geometry>
                <box size="0.30747057049766435 0.41971848716031573 0.25151090431794565" />
            </geometry>
            <material name="Green">
                <color rgba="0.1 0.9 0.1 0.9"/>
            </material>
        </visual>
        <collision>
            <origin xyz="0.0 -0.20985924358015787 0.0" rpy="0 0 0"/>
            <geometry>
                <box size="0.30747057049766435 0.41971848716031573 0.25151090431794565" />
            </geometry>
        </collision>
    </link>
    <joint name="Cube2_Cube3" type="revolute">
       <parent link="Cube2"/>
       <child  link="Cube3"/>
       <origin rpy="0 0 0" xyz="0.0 -0.41971848716031573 0.0" />
     <axis xyz="0 1 0"/>
       <limit effort="0.0" lower="-3.14159" upper="3.14159" velocity="0.0"/>
    </joint>
    <link name="Cube3">
        <inertial>
            <origin xyz="0.0 -0.17186105469726806 0.0" rpy="0 0 0"/>
            <mass value="1" />
            <inertia ixx="100" ixy="0" ixz="0" iyy="100" iyz="0" izz="100" />
        </inertial>
        <visual>
            <origin xyz="0.0 -0.17186105469726806 0.0" rpy="0 0 0"/>
            <geometry>
                <box size="0.2903378664849294 0.3437221093945361 0.22043319102189793" />
            </geometry>
            <material name="Green">
                <color rgba="0.1 0.9 0.1 0.9"/>
            </material>
        </visual>
        <collision>
            <origin xyz="0.0 -0.17186105469726806 0.0" rpy="0 0 0"/>
            <geometry>
                <box size="0.2903378664849294 0.3437221093945361 0.22043319102189793" />
            </geometry>
        </collision>
    </link>
    <joint name="Cube3_Cube4" type="revolute">
       <parent link="Cube3"/>
       <child  link="Cube4"/>
       <origin rpy="0 0 0" xyz="0.0 -0.17186105469726806 -0.11021659551094896" />
     <axis xyz="0 1 0"/>
       <limit effort="0.0" lower="-3.14159" upper="3.14159" velocity="0.0"/>
    </joint>
    <link name="Cube4">
        <inertial>
            <origin xyz="0.0 0.0 -0.10707378869341133" rpy="0 0 0"/>
            <mass value="1" />
            <inertia ixx="100" ixy="0" ixz="0" iyy="100" iyz="0" izz="100" />
        </inertial>
        <visual>
            <origin xyz="0.0 0.0 -0.10707378869341133" rpy="0 0 0"/>
            <geometry>
                <box size="0.2558004880727475 0.20197799816288894 0.21414757738682266" />
            </geometry>
            <material name="Green">
                <color rgba="0.1 0.9 0.1 0.9"/>
            </material>
        </visual>
        <collision>
            <origin xyz="0.0 0.0 -0.10707378869341133" rpy="0 0 0"/>
            <geometry>
                <box size="0.2558004880727475 0.20197799816288894 0.21414757738682266" />
            </geometry>
        </collision>
    </link>
    <joint name="Cube4_Cube5" type="revolute">
       <parent link="Cube4"/>
       <child  link="Cube5"/>
       <origin rpy="0 0 0" xyz="0.0 -0.10098899908144447 -0.10707378869341133" />
     <axis xyz="0 1 0"/>
       <limit effort="0.0" lower="-3.14159" upper="3.14159" velocity="0.0"/>
    </joint>
    <link name="Cube5">
        <inertial>
            <origin xyz="0.0 -0.10074089057023165 0.0" rpy="0 0 0"/>
            <mass value="1" />
            <inertia ixx="100" ixy="0" ixz="0" iyy="100" iyz="0" izz="100" />
        </inertial>
        <visual>
            <origin xyz="0.0 -0.10074089057023165 0.0" rpy="0 0 0"/>
            <geometry>
                <box size="0.2541707402491622 0.2014817811404633 0.21368841916039857" />
            </geometry>
            <material name="Blue">
                <color rgba="0.1 0.2 0.9 0.9"/>
            </material>
        </visual>
        <collision>
            <origin xyz="0.0 -0.10074089057023165 0.0" rpy="0 0 0"/>
            <geometry>
                <box size="0.2541707402491622 0.2014817811404633 0.21368841916039857" />
            </geometry>
        </collision>
    </link>
    <joint name="Cube0_Cube6" type="revolute">
       <parent link="Cube0"/>
       <child  link="Cube6"/>
       <origin rpy="0 0 0" xyz="0.0 0.7116943889073186 3" />
     <axis xyz="0 1 0"/>
       <limit effort="0.0" lower="-3.14159" upper="3.14159" velocity="0.0"/>
    </joint>
    <link name="Cube6">
        <inertial>
            <origin xyz="0.0 0.10048343815622017 0.0" rpy="0 0 0"/>
            <mass value="1" />
            <inertia ixx="100" ixy="0" ixz="0" iyy="100" iyz="0" izz="100" />
        </inertial>
        <visual>
            <origin xyz="0.0 0.10048343815622017 0.0" rpy="0 0 0"/>
            <geometry>
                <box size="0.24296914517727772 0.20096687631244034 0.21356401780061585" />
            </geometry>
            <material name="Blue">
                <color rgba="0.1 0.2 0.9 0.9"/>
            </material>
        </visual>
        <collision>
            <origin xyz="0.0 0.10048343815622017 0.0" rpy="0 0 0"/>
            <geometry>
                <box size="0.24296914517727772 0.20096687631244034 0.21356401780061585" />
            </geometry>
        </collision>
    </link>
    <joint name="Cube6_Cube7" type="revolute">
       <parent link="Cube6"/>
       <child  link="Cube7"/>
       <origin rpy="0 0 0" xyz="0.0 0.10048343815622017 -0.10678200890030792" />
     <axis xyz="0 1 0"/>
       <limit effort="0.0" lower="-3.14159" upper="3.14159" velocity="0.0"/>
    </joint>
    <link name="Cube7">
        <inertial>
            <origin xyz="0.0 0.0 -0.10040840517574544" rpy="0 0 0"/>
            <mass value="1" />
            <inertia ixx="100" ixy="0" ixz="0" iyy="100" iyz="0" izz="100" />
        </inertial>
        <visual>
            <origin xyz="0.0 0.0 -0.10040840517574544" rpy="0 0 0"/>
            <geometry>
                <box size="0.23187088481823906 0.20094912463871037 0.20081681035149088" />
            </geometry>
            <material name="Green">
                <color rgba="0.1 0.9 0.1 0.9"/>
            </material>
        </visual>
        <collision>
            <origin xyz="0.0 0.0 -0.10040840517574544" rpy="0 0 0"/>
            <geometry>
                <box size="0.23187088481823906 0.20094912463871037 0.20081681035149088" />
            </geometry>
        </collision>
    </link>
    <joint name="Cube7_Cube8" type="revolute">
       <parent link="Cube7"/>
       <child  link="Cube8"/>
       <origin rpy="0 0 0" xyz="0.0 0.0 -0.20081681035149088" />
     <axis xyz="0 1 0"/>
       <limit effort="0.0" lower="-3.14159" upper="3.14159" velocity="0.0"/>
    </joint>
    <link name="Cube8">
        <inertial>
            <origin xyz="0.0 0.0 -0.10032627313089164" rpy="0 0 0"/>
            <mass value="1" />
            <inertia ixx="100" ixy="0" ixz="0" iyy="100" iyz="0" izz="100" />
        </inertial>
        <visual>
            <origin xyz="0.0 0.0 -0.10032627313089164" rpy="0 0 0"/>
            <geometry>
                <box size="0.2190554749313029 0.20062413698411324 0.20065254626178328" />
            </geometry>
            <material name="Green">
                <color rgba="0.1 0.9 0.1 0.9"/>
            </material>
        </visual>
        <collision>
            <origin xyz="0.0 0.0 -0.10032627313089164" rpy="0 0 0"/>
            <geometry>
                <box size="0.2190554749313029 0.20062413698411324 0.20065254626178328" />
            </geometry>
        </collision>
    </link>
    <joint name="Cube8_Cube9" type="revolute">
       <parent link="Cube8"/>
       <child  link="Cube9"/>
       <origin rpy="0 0 0" xyz="0.0 0.10031206849205662 -0.10032627313089164" />
     <axis xyz="0 1 0"/>
       <limit effort="0.0" lower="-3.14159" upper="3.14159" velocity="0.0"/>
    </joint>
    <link name="Cube9">
        <inertial>
            <origin xyz="0.0 0.10003010152328197 0.0" rpy="0 0 0"/>
            <mass value="1" />
            <inertia ixx="100" ixy="0" ixz="0" iyy="100" iyz="0" izz="100" />
        </inertial>
        <visual>
            <origin xyz="0.0 0.10003010152328197 0.0" rpy="0 0 0"/>
            <geometry>
                <box size="0.2128595483990657 0.20006020304656394 0.2003801548010991" />
            </geometry>
            <material name="Blue">
                <color rgba="0.1 0.2 0.9 0.9"/>
            </material>
        </visual>
        <collision>
            <origin xyz="0.0 0.10003010152328197 0.0" rpy="0 0 0"/>
            <geometry>
                <box size="0.2128595483990657 0.20006020304656394 0.2003801548010991" />
            </geometry>
        </collision>
    </link>
    <joint name="Cube0_Cube10" type="revolute">
       <parent link="Cube0"/>
       <child  link="Cube10"/>
       <origin rpy="0 0 0" xyz="0.6341497369581581 0.0 3" />
     <axis xyz="0 1 0"/>
       <limit effort="0.0" lower="-3.14159" upper="3.14159" velocity="0.0"/>
    </joint>
    <link name="Cube10">
        <inertial>
            <origin xyz="0.3106103316309307 0.0 0.0" rpy="0 0 0"/>
            <mass value="1" />
            <inertia ixx="100" ixy="0" ixz="0" iyy="100" iyz="0" izz="100" />
        </inertial>
        <visual>
            <origin xyz="0.3106103316309307 0.0 0.0" rpy="0 0 0"/>
            <geometry>
                <box size="0.6212206632618614 1.4179685484635511 1.1547591136457607" />
            </geometry>
            <material name="Green">
                <color rgba="0.1 0.9 0.1 0.9"/>
            </material>
        </visual>
        <collision>
            <origin xyz="0.3106103316309307 0.0 0.0" rpy="0 0 0"/>
            <geometry>
                <box size="0.6212206632618614 1.4179685484635511 1.1547591136457607" />
            </geometry>
        </collision>
    </link>
    <joint name="Cube10_Cube11" type="revolute">
       <parent link="Cube10"/>
       <child  link="Cube11"/>
       <origin rpy="0 0 0" xyz="0.3106103316309307 -0.7089842742317756 0.0" />
     <axis xyz="0 1 0"/>
       <limit effort="0.0" lower="-3.14159" upper="3.14159" velocity="0.0"/>
    </joint>
    <link name="Cube11">
        <inertial>
            <origin xyz="0.0 -0.3054312241932913 0.0" rpy="0 0 0"/>
            <mass value="1" />
            <inertia ixx="100" ixy="0" ixz="0" iyy="100" iyz="0" izz="100" />
        </inertial>
        <visual>
            <origin xyz="0.0 -0.3054312241932913 0.0" rpy="0 0 0"/>
            <geometry>
                <box size="0.27780385196931034 0.6108624483865825 1.0640217266446255" />
            </geometry>
            <material name="Blue">
                <color rgba="0.1 0.2 0.9 0.9"/>
            </material>
        </visual>
        <collision>
            <origin xyz="0.0 -0.3054312241932913 0.0" rpy="0 0 0"/>
            <geometry>
                <box size="0.27780385196931034 0.6108624483865825 1.0640217266446255" />
            </geometry>
        </collision>
    </link>
    <joint name="Cube11_Cube12" type="revolute">
       <parent link="Cube11"/>
       <child  link="Cube12"/>
       <origin rpy="0 0 0" xyz="0.0 -0.3054312241932913 -0.5320108633223127" />
     <axis xyz="0 1 0"/>
       <limit effort="0.0" lower="-3.14159" upper="3.14159" velocity="0.0"/>
    </joint>
    <link name="Cube12">
        <inertial>
            <origin xyz="0.0 0.0 -0.44519512475876466" rpy="0 0 0"/>
            <mass value="1" />
            <inertia ixx="100" ixy="0" ixz="0" iyy="100" iyz="0" izz="100" />
        </inertial>
        <visual>
            <origin xyz="0.0 0.0 -0.44519512475876466" rpy="0 0 0"/>
            <geometry>
                <box size="0.23932044667938676 0.5966669129651174 0.8903902495175293" />
            </geometry>
            <material name="Green">
                <color rgba="0.1 0.9 0.1 0.9"/>
            </material>
        </visual>
        <collision>
            <origin xyz="0.0 0.0 -0.44519512475876466" rpy="0 0 0"/>
            <geometry>
                <box size="0.23932044667938676 0.5966669129651174 0.8903902495175293" />
            </geometry>
        </collision>
    </link>
    <joint name="Cube10_Cube13" type="revolute">
       <parent link="Cube10"/>
       <child  link="Cube13"/>
       <origin rpy="0 0 0" xyz="-0.3106103316309307 0.7089842742317756 0.0" />
     <axis xyz="0 1 0"/>
       <limit effort="0.0" lower="-3.14159" upper="3.14159" velocity="0.0"/>
    </joint>
    <link name="Cube13">
        <inertial>
            <origin xyz="0.0 0.18640201240069643 0.0" rpy="0 0 0"/>
            <mass value="1" />
            <inertia ixx="100" ixy="0" ixz="0" iyy="100" iyz="0" izz="100" />
        </inertial>
        <visual>
            <origin xyz="0.0 0.18640201240069643 0.0" rpy="0 0 0"/>
            <geometry>
                <box size="0.21905863813412382 0.37280402480139285 0.48502560807166006" />
            </geometry>
            <material name="Green">
                <color rgba="0.1 0.9 0.1 0.9"/>
            </material>
        </visual>
        <collision>
            <origin xyz="0.0 0.18640201240069643 0.0" rpy="0 0 0"/>
            <geometry>
                <box size="0.21905863813412382 0.37280402480139285 0.48502560807166006" />
            </geometry>
        </collision>
    </link>
    <joint name="Cube10_Cube14" type="revolute">
       <parent link="Cube10"/>
       <child  link="Cube14"/>
       <origin rpy="0 0 0" xyz="0.6212206632618614 0.0 0.0" />
     <axis xyz="0 1 0"/>
       <limit effort="0.0" lower="-3.14159" upper="3.14159" velocity="0.0"/>
    </joint>
    <link name="Cube14">
        <inertial>
            <origin xyz="0.2612474091045878 0.0 0.0" rpy="0 0 0"/>
            <mass value="1" />
            <inertia ixx="100" ixy="0" ixz="0" iyy="100" iyz="0" izz="100" />
        </inertial>
        <visual>
            <origin xyz="0.2612474091045878 0.0 0.0" rpy="0 0 0"/>
            <geometry>
                <box size="0.5224948182091756 1.083169459367129 1.3895074880943787" />
            </geometry>
            <material name="Blue">
                <color rgba="0.1 0.2 0.9 0.9"/>
            </material>
        </visual>
        <collision>
            <origin xyz="0.2612474091045878 0.0 0.0" rpy="0 0 0"/>
            <geometry>
                <box size="0.5224948182091756 1.083169459367129 1.3895074880943787" />
            </geometry>
        </collision>
    </link>
    <joint name="Cube14_Cube15" type="revolute">
       <parent link="Cube14"/>
       <child  link="Cube15"/>
       <origin rpy="0 0 0" xyz="0.2612474091045878 -0.5415847296835645 0.0" />
     <axis xyz="0 1 0"/>
       <limit effort="0.0" lower="-3.14159" upper="3.14159" velocity="0.0"/>
    </joint>
    <link name="Cube15">
        <inertial>
            <origin xyz="0.0 -0.3088162618352394 0.0" rpy="0 0 0"/>
            <mass value="1" />
            <inertia ixx="100" ixy="0" ixz="0" iyy="100" iyz="0" izz="100" />
        </inertial>
        <visual>
            <origin xyz="0.0 -0.3088162618352394 0.0" rpy="0 0 0"/>
            <geometry>
                <box size="0.2672954720131415 0.6176325236704788 0.2734941864928033" />
            </geometry>
            <material name="Blue">
                <color rgba="0.1 0.2 0.9 0.9"/>
            </material>
        </visual>
        <collision>
            <origin xyz="0.0 -0.3088162618352394 0.0" rpy="0 0 0"/>
            <geometry>
                <box size="0.2672954720131415 0.6176325236704788 0.2734941864928033" />
            </geometry>
        </collision>
    </link>
    <joint name="Cube15_Cube16" type="revolute">
       <parent link="Cube15"/>
       <child  link="Cube16"/>
       <origin rpy="0 0 0" xyz="0.0 -0.3088162618352394 -0.13674709324640166" />
     <axis xyz="0 1 0"/>
       <limit effort="0.0" lower="-3.14159" upper="3.14159" velocity="0.0"/>
    </joint>
    <link name="Cube16">
        <inertial>
            <origin xyz="0.0 0.0 -0.10646830428515756" rpy="0 0 0"/>
            <mass value="1" />
            <inertia ixx="100" ixy="0" ixz="0" iyy="100" iyz="0" izz="100" />
        </inertial>
        <visual>
            <origin xyz="0.0 0.0 -0.10646830428515756" rpy="0 0 0"/>
            <geometry>
                <box size="0.24361657548372342 0.308596943464405 0.21293660857031513" />
            </geometry>
            <material name="Blue">
                <color rgba="0.1 0.2 0.9 0.9"/>
            </material>
        </visual>
        <collision>
            <origin xyz="0.0 0.0 -0.10646830428515756" rpy="0 0 0"/>
            <geometry>
                <box size="0.24361657548372342 0.308596943464405 0.21293660857031513" />
            </geometry>
        </collision>
    </link>
    <joint name="Cube16_Cube17" type="revolute">
       <parent link="Cube16"/>
       <child  link="Cube17"/>
       <origin rpy="0 0 0" xyz="0.0 0.0 -0.21293660857031513" />
     <axis xyz="0 1 0"/>
       <limit effort="0.0" lower="-3.14159" upper="3.14159" velocity="0.0"/>
    </joint>
    <link name="Cube17">
        <inertial>
            <origin xyz="0.0 0.0 -0.10252691242999533" rpy="0 0 0"/>
            <mass value="1" />
            <inertia ixx="100" ixy="0" ixz="0" iyy="100" iyz="0" izz="100" />
        </inertial>
        <visual>
            <origin xyz="0.0 0.0 -0.10252691242999533" rpy="0 0 0"/>
            <geometry>
                <box size="0.2245358219191934 0.2310131237003245 0.20505382485999066" />
            </geometry>
            <material name="Green">
                <color rgba="0.1 0.9 0.1 0.9"/>
            </material>
        </visual>
        <collision>
            <origin xyz="0.0 0.0 -0.10252691242999533" rpy="0 0 0"/>
            <geometry>
                <box size="0.2245358219191934 0.2310131237003245 0.20505382485999066" />
            </geometry>
        </collision>
    </link>
    <joint name="Cube17_Cube18" type="revolute">
       <parent link="Cube17"/>
       <child  link="Cube18"/>
       <origin rpy="0 0 0" xyz="0.0 -0.11550656185016225 -0.10252691242999533" />
     <axis xyz="0 1 0"/>
       <limit effort="0.0" lower="-3.14159" upper="3.14159" velocity="0.0"/>
    </joint>
    <link name="Cube18">
        <inertial>
            <origin xyz="0.0 -0.10874249993889876 0.0" rpy="0 0 0"/>
            <mass value="1" />
            <inertia ixx="100" ixy="0" ixz="0" iyy="100" iyz="0" izz="100" />
        </inertial>
        <visual>
            <origin xyz="0.0 -0.10874249993889876 0.0" rpy="0 0 0"/>
            <geometry>
                <box size="0.22144238656997256 0.2174849998777975 0.2027680421825774" />
            </geometry>
            <material name="Blue">
                <color rgba="0.1 0.2 0.9 0.9"/>
            </material>
        </visual>
        <collision>
            <origin xyz="0.0 -0.10874249993889876 0.0" rpy="0 0 0"/>
            <geometry>
                <box size="0.22144238656997256 0.2174849998777975 0.2027680421825774" />
            </geometry>
        </collision>
    </link>
    <joint name="Cube18_Cube19" type="revolute">
       <parent link="Cube18"/>
       <child  link="Cube19"/>
       <origin rpy="0 0 0" xyz="0.0 -0.10874249993889876 -0.1013840210912887" />
     <axis xyz="0 1 0"/>
       <limit effort="0.0" lower="-3.14159" upper="3.14159" velocity="0.0"/>
    </joint>
    <link name="Cube19">
        <inertial>
            <origin xyz="0.0 0.0 -0.10008795795667698" rpy="0 0 0"/>
            <mass value="1" />
            <inertia ixx="100" ixy="0" ixz="0" iyy="100" iyz="0" izz="100" />
        </inertial>
        <visual>
            <origin xyz="0.0 0.0 -0.10008795795667698" rpy="0 0 0"/>
            <geometry>
                <box size="0.20217415266835767 0.20148254109920516 0.20017591591335396" />
            </geometry>
            <material name="Blue">
                <color rgba="0.1 0.2 0.9 0.9"/>
            </material>
        </visual>
        <collision>
            <origin xyz="0.0 0.0 -0.10008795795667698" rpy="0 0 0"/>
            <geometry>
                <box size="0.20217415266835767 0.20148254109920516 0.20017591591335396" />
            </geometry>
        </collision>
    </link>
    <joint name="Cube14_Cube20" type="revolute">
       <parent link="Cube14"/>
       <child  link="Cube20"/>
       <origin rpy="0 0 0" xyz="-0.2612474091045878 0.5415847296835645 0.0" />
     <axis xyz="0 1 0"/>
       <limit effort="0.0" lower="-3.14159" upper="3.14159" velocity="0.0"/>
    </joint>
    <link name="Cube20">
        <inertial>
            <origin xyz="0.0 0.1006656088074073 0.0" rpy="0 0 0"/>
            <mass value="1" />
            <inertia ixx="100" ixy="0" ixz="0" iyy="100" iyz="0" izz="100" />
        </inertial>
        <visual>
            <origin xyz="0.0 0.1006656088074073 0.0" rpy="0 0 0"/>
            <geometry>
                <box size="0.20018434306381502 0.2013312176148146 0.20010155369690924" />
            </geometry>
            <material name="Green">
                <color rgba="0.1 0.9 0.1 0.9"/>
            </material>
        </visual>
        <collision>
            <origin xyz="0.0 0.1006656088074073 0.0" rpy="0 0 0"/>
            <geometry>
                <box size="0.20018434306381502 0.2013312176148146 0.20010155369690924" />
            </geometry>
        </collision>
    </link>
    <joint name="Cube20_Cube21" type="revolute">
       <parent link="Cube20"/>
       <child  link="Cube21"/>
       <origin rpy="0 0 0" xyz="0.0 0.1006656088074073 -0.10005077684845462" />
     <axis xyz="0 1 0"/>
       <limit effort="0.0" lower="-3.14159" upper="3.14159" velocity="0.0"/>
    </joint>
    <link name="Cube21">
        <inertial>
            <origin xyz="0.0 0.0 -0.10003191108114091" rpy="0 0 0"/>
            <mass value="1" />
            <inertia ixx="100" ixy="0" ixz="0" iyy="100" iyz="0" izz="100" />
        </inertial>
        <visual>
            <origin xyz="0.0 0.0 -0.10003191108114091" rpy="0 0 0"/>
            <geometry>
                <box size="0.20015722178190706 0.20038349277233775 0.20006382216228183" />
            </geometry>
            <material name="Green">
                <color rgba="0.1 0.9 0.1 0.9"/>
            </material>
        </visual>
        <collision>
            <origin xyz="0.0 0.0 -0.10003191108114091" rpy="0 0 0"/>
            <geometry>
                <box size="0.20015722178190706 0.20038349277233775 0.20006382216228183" />
            </geometry>
        </collision>
    </link>
    <joint name="Cube21_Cube22" type="revolute">
       <parent link="Cube21"/>
       <child  link="Cube22"/>
       <origin rpy="0 0 0" xyz="0.0 0.10019174638616887 -0.10003191108114091" />
     <axis xyz="0 1 0"/>
       <limit effort="0.0" lower="-3.14159" upper="3.14159" velocity="0.0"/>
    </joint>
    <link name="Cube22">
        <inertial>
            <origin xyz="0.0 0.10011722096379737 0.0" rpy="0 0 0"/>
            <mass value="1" />
            <inertia ixx="100" ixy="0" ixz="0" iyy="100" iyz="0" izz="100" />
        </inertial>
        <visual>
            <origin xyz="0.0 0.10011722096379737 0.0" rpy="0 0 0"/>
            <geometry>
                <box size="0.20005897171143308 0.20023444192759474 0.2000257136258382" />
            </geometry>
            <material name="Blue">
                <color rgba="0.1 0.2 0.9 0.9"/>
            </material>
        </visual>
        <collision>
            <origin xyz="0.0 0.10011722096379737 0.0" rpy="0 0 0"/>
            <geometry>
                <box size="0.20005897171143308 0.20023444192759474 0.2000257136258382" />
            </geometry>
        </collision>
    </link>
    <joint name="Cube22_Cube23" type="revolute">
       <parent link="Cube22"/>
       <child  link="Cube23"/>
       <origin rpy="0 0 0" xyz="0.0 0.10011722096379737 -0.1000128568129191" />
     <axis xyz="0 1 0"/>
       <limit effort="0.0" lower="-3.14159" upper="3.14159" velocity="0.0"/>
    </joint>
    <link name="Cube23">
        <inertial>
            <origin xyz="0.0 0.0 -0.10000306385911953" rpy="0 0 0"/>
            <mass value="1" />
            <inertia ixx="100" ixy="0" ixz="0" iyy="100" iyz="0" izz="100" />
        </inertial>
        <visual>
            <origin xyz="0.0 0.0 -0.10000306385911953" rpy="0 0 0"/>
            <geometry>
                <box size="0.2000115321098065 0.20005502350467622 0.20000612771823906" />
            </geometry>
            <material name="Blue">
                <color rgba="0.1 0.2 0.9 0.9"/>
            </material>
        </visual>
        <collision>
            <origin xyz="0.0 0.0 -0.10000306385911953" rpy="0 0 0"/>
            <geometry>
                <box size="0.2000115321098065 0.20005502350467622 0.20000612771823906" />
            </geometry>
        </collision>
    </link>
    <joint name="Cube14_Cube24" type="revolute">
       <parent link="Cube14"/>
       <child  link="Cube24"/>
       <origin rpy="0 0 0" xyz="0.5224948182091756 0.0 0.0" />
     <axis xyz="0 1 0"/>
       <limit effort="0.0" lower="-3.14159" upper="3.14159" velocity="0.0"/>
    </joint>
    <link name="Cube24">
        <inertial>
            <origin xyz="0.23293844641887562 0.0 0.0" rpy="0 0 0"/>
            <mass value="1" />
            <inertia ixx="100" ixy="0" ixz="0" iyy="100" iyz="0" izz="100" />
        </inertial>
        <visual>
            <origin xyz="0.23293844641887562 0.0 0.0" rpy="0 0 0"/>
            <geometry>
                <box size="0.46587689283775124 1.3592814134152598 0.44662948007117265" />
            </geometry>
            <material name="Green">
                <color rgba="0.1 0.9 0.1 0.9"/>
            </material>
        </visual>
        <collision>
            <origin xyz="0.23293844641887562 0.0 0.0" rpy="0 0 0"/>
            <geometry>
                <box size="0.46587689283775124 1.3592814134152598 0.44662948007117265" />
            </geometry>
        </collision>
    </link>
    <joint name="Cube24_Cube25" type="revolute">
       <parent link="Cube24"/>
       <child  link="Cube25"/>
       <origin rpy="0 0 0" xyz="0.23293844641887562 -0.6796407067076299 0.0" />
     <axis xyz="0 1 0"/>
       <limit effort="0.0" lower="-3.14159" upper="3.14159" velocity="0.0"/>
    </joint>
    <link name="Cube25">
        <inertial>
            <origin xyz="0.0 -0.5280656189886812 0.0" rpy="0 0 0"/>
            <mass value="1" />
            <inertia ixx="100" ixy="0" ixz="0" iyy="100" iyz="0" izz="100" />
        </inertial>
        <visual>
            <origin xyz="0.0 -0.5280656189886812 0.0" rpy="0 0 0"/>
            <geometry>
                <box size="0.22348186382209628 1.0561312379773624 0.3612393536974212" />
            </geometry>
            <material name="Blue">
                <color rgba="0.1 0.2 0.9 0.9"/>
            </material>
        </visual>
        <collision>
            <origin xyz="0.0 -0.5280656189886812 0.0" rpy="0 0 0"/>
            <geometry>
                <box size="0.22348186382209628 1.0561312379773624 0.3612393536974212" />
            </geometry>
        </collision>
    </link>
    <joint name="Cube24_Cube26" type="revolute">
       <parent link="Cube24"/>
       <child  link="Cube26"/>
       <origin rpy="0 0 0" xyz="-0.23293844641887562 0.6796407067076299 0.0" />
     <axis xyz="0 1 0"/>
       <limit effort="0.0" lower="-3.14159" upper="3.14159" velocity="0.0"/>
    </joint>
    <link name="Cube26">
        <inertial>
            <origin xyz="0.0 0.5164059511302419 0.0" rpy="0 0 0"/>
            <mass value="1" />
            <inertia ixx="100" ixy="0" ixz="0" iyy="100" iyz="0" izz="100" />
        </inertial>
        <visual>
            <origin xyz="0.0 0.5164059511302419 0.0" rpy="0 0 0"/>
            <geometry>
                <box size="0.21837162608595564 1.0328119022604838 0.2939478075519693" />
            </geometry>
            <material name="Blue">
                <color rgba="0.1 0.2 0.9 0.9"/>
            </material>
        </visual>
        <collision>
            <origin xyz="0.0 0.5164059511302419 0.0" rpy="0 0 0"/>
            <geometry>
                <box size="0.21837162608595564 1.0328119022604838 0.2939478075519693" />
            </geometry>
        </collision>
    </link>
    <joint name="Cube26_Cube27" type="revolute">
       <parent link="Cube26"/>
       <child  link="Cube27"/>
       <origin rpy="0 0 0" xyz="0.0 0.5164059511302419 -0.14697390377598465" />
     <axis xyz="0 1 0"/>
       <limit effort="0.0" lower="-3.14159" upper="3.14159" velocity="0.0"/>
    </joint>
    <link name="Cube27">
        <inertial>
            <origin xyz="0.0 0.0 -0.1260084290661339" rpy="0 0 0"/>
            <mass value="1" />
            <inertia ixx="100" ixy="0" ixz="0" iyy="100" iyz="0" izz="100" />
        </inertial>
        <visual>
            <origin xyz="0.0 0.0 -0.1260084290661339" rpy="0 0 0"/>
            <geometry>
                <box size="0.20981604582352084 0.9216451306497997 0.2520168581322678" />
            </geometry>
            <material name="Green">
                <color rgba="0.1 0.9 0.1 0.9"/>
            </material>
        </visual>
        <collision>
            <origin xyz="0.0 0.0 -0.1260084290661339" rpy="0 0 0"/>
            <geometry>
                <box size="0.20981604582352084 0.9216451306497997 0.2520168581322678" />
            </geometry>
        </collision>
    </link>
    <joint name="Cube27_Cube28" type="revolute">
       <parent link="Cube27"/>
       <child  link="Cube28"/>
       <origin rpy="0 0 0" xyz="0.0 0.0 -0.2520168581322678" />
     <axis xyz="0 1 0"/>
       <limit effort="0.0" lower="-3.14159" upper="3.14159" velocity="0.0"/>
    </joint>
    <link name="Cube28">
        <inertial>
            <origin xyz="0.0 0.0 -0.10564163666743046" rpy="0 0 0"/>
            <mass value="1" />
            <inertia ixx="100" ixy="0" ixz="0" iyy="100" iyz="0" izz="100" />
        </inertial>
        <visual>
            <origin xyz="0.0 0.0 -0.10564163666743046" rpy="0 0 0"/>
            <geometry>
                <box size="0.20043943132849582 0.23219218975012548 0.2112832733348609" />
            </geometry>
            <material name="Green">
                <color rgba="0.1 0.9 0.1 0.9"/>
            </material>
        </visual>
        <collision>
            <origin xyz="0.0 0.0 -0.10564163666743046" rpy="0 0 0"/>
            <geometry>
                <box size="0.20043943132849582 0.23219218975012548 0.2112832733348609" />
            </geometry>
        </collision>
    </link>
    <joint name="Cube24_Cube29" type="revolute">
       <parent link="Cube24"/>
       <child  link="Cube29"/>
       <origin rpy="0 0 0" xyz="0.46587689283775124 0.0 0.0" />
     <axis xyz="0 1 0"/>
       <limit effort="0.0" lower="-3.14159" upper="3.14159" velocity="0.0"/>
    </joint>
    <link name="Cube29">
        <inertial>
            <origin xyz="0.5776429362758999 0.0 0.0" rpy="0 0 0"/>
            <mass value="1" />
            <inertia ixx="100" ixy="0" ixz="0" iyy="100" iyz="0" izz="100" />
        </inertial>
        <visual>
            <origin xyz="0.5776429362758999 0.0 0.0" rpy="0 0 0"/>
            <geometry>
                <box size="1.1552858725517998 0.7558986089816284 0.8095019299429116" />
            </geometry>
            <material name="Green">
                <color rgba="0.1 0.9 0.1 0.9"/>
            </material>
        </visual>
        <collision>
            <origin xyz="0.5776429362758999 0.0 0.0" rpy="0 0 0"/>
            <geometry>
                <box size="1.1552858725517998 0.7558986089816284 0.8095019299429116" />
            </geometry>
        </collision>
    </link>
</robot>