<robot name = "robot">
    <link name="Cube0">
        <inertial>
            <origin xyz="0.0 0.0 3" rpy="0 0 0"/>
            <mass value="1" />
            <inertia ixx="100" ixy="0" ixz="0" iyy="100" iyz="0" izz="100" />
        </inertial>
        <visual>
            <origin xyz="0.0 0.0 3" rpy="0 0 0"/>
            <geometry>
                <box size="1.1459338181466834 0.2762827722053154 0.32238620168864496" />
            </geometry>
            <material name="Green">
                <color rgba="0.1 0.9 0.1 0.9"/>
            </material>
        </visual>
        <collision>
            <origin xyz="0.0 0.0 3" rpy="0 0 0"/>
            <geometry>
                <box size="1.1459338181466834 0.2762827722053154 0.32238620168864496" />
            </geometry>
        </collision>
    </link>
    <joint name="Cube0_Cube1" type="fixed">
       <parent link="Cube0"/>
       <child  link="Cube1"/>
       <origin rpy="0 0 0" xyz="0.0 -0.1381413861026577 3" />
     <axis xyz="0 1 0"/>
       <limit effort="0.0" lower="-3.14159" upper="3.14159" velocity="0.0"/>
    </joint>
    <link name="Cube1">
        <inertial>
            <origin xyz="0.0 -0.13164679697935697 0.0" rpy="0 0 0"/>
            <mass value="1" />
            <inertia ixx="100" ixy="0" ixz="0" iyy="100" iyz="0" izz="100" />
        </inertial>
        <visual>
            <origin xyz="0.0 -0.13164679697935697 0.0" rpy="0 0 0"/>
            <geometry>
                <box size="0.28533981183273444 0.26329359395871393 0.28656500589533096" />
            </geometry>
            <material name="Green">
                <color rgba="0.1 0.9 0.1 0.9"/>
            </material>
        </visual>
        <collision>
            <origin xyz="0.0 -0.13164679697935697 0.0" rpy="0 0 0"/>
            <geometry>
                <box size="0.28533981183273444 0.26329359395871393 0.28656500589533096" />
            </geometry>
        </collision>
    </link>
    <joint name="Cube1_Cube2" type="prismatic">
       <parent link="Cube1"/>
       <child  link="Cube2"/>
       <origin rpy="0 0 0" xyz="0.0 -0.26329359395871393 0.0" />
     <axis xyz="0 1 0"/>
       <limit effort="0.0" lower="-3.14159" upper="3.14159" velocity="0.0"/>
    </joint>
    <link name="Cube2">
        <inertial>
            <origin xyz="0.0 -0.1333148369399284 0.0" rpy="0 0 0"/>
            <mass value="1" />
            <inertia ixx="100" ixy="0" ixz="0" iyy="100" iyz="0" izz="100" />
        </inertial>
        <visual>
            <origin xyz="0.0 -0.1333148369399284 0.0" rpy="0 0 0"/>
            <geometry>
                <box size="0.6784111604526679 0.2666296738798568 0.2377897537539046" />
            </geometry>
            <material name="Blue">
                <color rgba="0.1 0.2 0.9 0.9"/>
            </material>
        </visual>
        <collision>
            <origin xyz="0.0 -0.1333148369399284 0.0" rpy="0 0 0"/>
            <geometry>
                <box size="0.6784111604526679 0.2666296738798568 0.2377897537539046" />
            </geometry>
        </collision>
    </link>
    <joint name="Cube2_Cube3" type="revolute">
       <parent link="Cube2"/>
       <child  link="Cube3"/>
       <origin rpy="0 0 0" xyz="0.0 -0.2666296738798568 0.0" />
     <axis xyz="0 1 0"/>
       <limit effort="0.0" lower="-3.14159" upper="3.14159" velocity="0.0"/>
    </joint>
    <link name="Cube3">
        <inertial>
            <origin xyz="0.0 -0.12616019974669254 0.0" rpy="0 0 0"/>
            <mass value="1" />
            <inertia ixx="100" ixy="0" ixz="0" iyy="100" iyz="0" izz="100" />
        </inertial>
        <visual>
            <origin xyz="0.0 -0.12616019974669254 0.0" rpy="0 0 0"/>
            <geometry>
                <box size="0.3089585581996639 0.2523203994933851 0.29003245192973215" />
            </geometry>
            <material name="Green">
                <color rgba="0.1 0.9 0.1 0.9"/>
            </material>
        </visual>
        <collision>
            <origin xyz="0.0 -0.12616019974669254 0.0" rpy="0 0 0"/>
            <geometry>
                <box size="0.3089585581996639 0.2523203994933851 0.29003245192973215" />
            </geometry>
        </collision>
    </link>
    <joint name="Cube3_Cube4" type="revolute">
       <parent link="Cube3"/>
       <child  link="Cube4"/>
       <origin rpy="0 0 0" xyz="0.0 -0.12616019974669254 -0.14501622596486607" />
     <axis xyz="0 1 0"/>
       <limit effort="0.0" lower="-3.14159" upper="3.14159" velocity="0.0"/>
    </joint>
    <link name="Cube4">
        <inertial>
            <origin xyz="0.0 0.0 -0.1238183108813692" rpy="0 0 0"/>
            <mass value="1" />
            <inertia ixx="100" ixy="0" ixz="0" iyy="100" iyz="0" izz="100" />
        </inertial>
        <visual>
            <origin xyz="0.0 0.0 -0.1238183108813692" rpy="0 0 0"/>
            <geometry>
                <box size="0.9146439731715064 0.2745234242995004 0.2476366217627384" />
            </geometry>
            <material name="Blue">
                <color rgba="0.1 0.2 0.9 0.9"/>
            </material>
        </visual>
        <collision>
            <origin xyz="0.0 0.0 -0.1238183108813692" rpy="0 0 0"/>
            <geometry>
                <box size="0.9146439731715064 0.2745234242995004 0.2476366217627384" />
            </geometry>
        </collision>
    </link>
    <joint name="Cube0_Cube5" type="spherical">
       <parent link="Cube0"/>
       <child  link="Cube5"/>
       <origin rpy="0 0 0" xyz="0.0 0.1381413861026577 3" />
     <axis xyz="0 1 0"/>
       <limit effort="0.0" lower="-3.14159" upper="3.14159" velocity="0.0"/>
    </joint>
    <link name="Cube5">
        <inertial>
            <origin xyz="0.0 0.11724320382055174 0.0" rpy="0 0 0"/>
            <mass value="1" />
            <inertia ixx="100" ixy="0" ixz="0" iyy="100" iyz="0" izz="100" />
        </inertial>
        <visual>
            <origin xyz="0.0 0.11724320382055174 0.0" rpy="0 0 0"/>
            <geometry>
                <box size="0.6417191004565326 0.23448640764110348 0.2579857603423419" />
            </geometry>
            <material name="Blue">
                <color rgba="0.1 0.2 0.9 0.9"/>
            </material>
        </visual>
        <collision>
            <origin xyz="0.0 0.11724320382055174 0.0" rpy="0 0 0"/>
            <geometry>
                <box size="0.6417191004565326 0.23448640764110348 0.2579857603423419" />
            </geometry>
        </collision>
    </link>
    <joint name="Cube5_Cube6" type="prismatic">
       <parent link="Cube5"/>
       <child  link="Cube6"/>
       <origin rpy="0 0 0" xyz="0.0 0.11724320382055174 -0.12899288017117094" />
     <axis xyz="0 1 0"/>
       <limit effort="0.0" lower="-3.14159" upper="3.14159" velocity="0.0"/>
    </joint>
    <link name="Cube6">
        <inertial>
            <origin xyz="0.0 0.0 -0.10278714514711369" rpy="0 0 0"/>
            <mass value="1" />
            <inertia ixx="100" ixy="0" ixz="0" iyy="100" iyz="0" izz="100" />
        </inertial>
        <visual>
            <origin xyz="0.0 0.0 -0.10278714514711369" rpy="0 0 0"/>
            <geometry>
                <box size="0.7407438708422376 0.2206232862167036 0.20557429029422739" />
            </geometry>
            <material name="Green">
                <color rgba="0.1 0.9 0.1 0.9"/>
            </material>
        </visual>
        <collision>
            <origin xyz="0.0 0.0 -0.10278714514711369" rpy="0 0 0"/>
            <geometry>
                <box size="0.7407438708422376 0.2206232862167036 0.20557429029422739" />
            </geometry>
        </collision>
    </link>
    <joint name="Cube6_Cube7" type="fixed">
       <parent link="Cube6"/>
       <child  link="Cube7"/>
       <origin rpy="0 0 0" xyz="0.0 0.0 -0.20557429029422739" />
     <axis xyz="0 1 0"/>
       <limit effort="0.0" lower="-3.14159" upper="3.14159" velocity="0.0"/>
    </joint>
    <link name="Cube7">
        <inertial>
            <origin xyz="0.0 0.0 -0.14955182898350305" rpy="0 0 0"/>
            <mass value="1" />
            <inertia ixx="100" ixy="0" ixz="0" iyy="100" iyz="0" izz="100" />
        </inertial>
        <visual>
            <origin xyz="0.0 0.0 -0.14955182898350305" rpy="0 0 0"/>
            <geometry>
                <box size="0.9637879053241933 0.25050106875575723 0.2991036579670061" />
            </geometry>
            <material name="Green">
                <color rgba="0.1 0.9 0.1 0.9"/>
            </material>
        </visual>
        <collision>
            <origin xyz="0.0 0.0 -0.14955182898350305" rpy="0 0 0"/>
            <geometry>
                <box size="0.9637879053241933 0.25050106875575723 0.2991036579670061" />
            </geometry>
        </collision>
    </link>
    <joint name="Cube7_Cube8" type="fixed">
       <parent link="Cube7"/>
       <child  link="Cube8"/>
       <origin rpy="0 0 0" xyz="0.0 0.12525053437787861 -0.14955182898350305" />
     <axis xyz="0 1 0"/>
       <limit effort="0.0" lower="-3.14159" upper="3.14159" velocity="0.0"/>
    </joint>
    <link name="Cube8">
        <inertial>
            <origin xyz="0.0 0.10021409261720977 0.0" rpy="0 0 0"/>
            <mass value="1" />
            <inertia ixx="100" ixy="0" ixz="0" iyy="100" iyz="0" izz="100" />
        </inertial>
        <visual>
            <origin xyz="0.0 0.10021409261720977 0.0" rpy="0 0 0"/>
            <geometry>
                <box size="0.6936367946728837 0.20042818523441955 0.22758302614990142" />
            </geometry>
            <material name="Blue">
                <color rgba="0.1 0.2 0.9 0.9"/>
            </material>
        </visual>
        <collision>
            <origin xyz="0.0 0.10021409261720977 0.0" rpy="0 0 0"/>
            <geometry>
                <box size="0.6936367946728837 0.20042818523441955 0.22758302614990142" />
            </geometry>
        </collision>
    </link>
</robot>