<robot name = "robot">
    <link name="Cube0">
        <inertial>
            <origin xyz="0.0 0.0 3" rpy="0 0 0"/>
            <mass value="1" />
            <inertia ixx="100" ixy="0" ixz="0" iyy="100" iyz="0" izz="100" />
        </inertial>
        <visual>
            <origin xyz="0.0 0.0 3" rpy="0 0 0"/>
            <geometry>
                <box size="0.3017352493162563 1.1499378881277058 0.8384181315752945" />
            </geometry>
            <material name="Blue">
                <color rgba="0.1 0.2 0.9 0.9"/>
            </material>
        </visual>
        <collision>
            <origin xyz="0.0 0.0 3" rpy="0 0 0"/>
            <geometry>
                <box size="0.3017352493162563 1.1499378881277058 0.8384181315752945" />
            </geometry>
        </collision>
    </link>
    <joint name="Cube0_Cube1" type="revolute">
       <parent link="Cube0"/>
       <child  link="Cube1"/>
       <origin rpy="0 0 0" xyz="0.0 -0.5749689440638529 3" />
     <axis xyz="0 1 0"/>
       <limit effort="0.0" lower="-3.14159" upper="3.14159" velocity="0.0"/>
    </joint>
    <link name="Cube1">
        <inertial>
            <origin xyz="0.0 -0.39404977145340137 0.0" rpy="0 0 0"/>
            <mass value="1" />
            <inertia ixx="100" ixy="0" ixz="0" iyy="100" iyz="0" izz="100" />
        </inertial>
        <visual>
            <origin xyz="0.0 -0.39404977145340137 0.0" rpy="0 0 0"/>
            <geometry>
                <box size="0.26811561673452017 0.7880995429068027 0.4182990373218688" />
            </geometry>
            <material name="Green">
                <color rgba="0.1 0.9 0.1 0.9"/>
            </material>
        </visual>
        <collision>
            <origin xyz="0.0 -0.39404977145340137 0.0" rpy="0 0 0"/>
            <geometry>
                <box size="0.26811561673452017 0.7880995429068027 0.4182990373218688" />
            </geometry>
        </collision>
    </link>
    <joint name="Cube1_Cube2" type="revolute">
       <parent link="Cube1"/>
       <child  link="Cube2"/>
       <origin rpy="0 0 0" xyz="0.0 -0.7880995429068027 0.0" />
     <axis xyz="0 1 0"/>
       <limit effort="0.0" lower="-3.14159" upper="3.14159" velocity="0.0"/>
    </joint>
    <link name="Cube2">
        <inertial>
            <origin xyz="0.0 -0.17891535260447497 0.0" rpy="0 0 0"/>
            <mass value="1" />
            <inertia ixx="100" ixy="0" ixz="0" iyy="100" iyz="0" izz="100" />
        </inertial>
        <visual>
            <origin xyz="0.0 -0.17891535260447497 0.0" rpy="0 0 0"/>
            <geometry>
                <box size="0.2330897974952698 0.35783070520894994 0.3147667609680614" />
            </geometry>
            <material name="Blue">
                <color rgba="0.1 0.2 0.9 0.9"/>
            </material>
        </visual>
        <collision>
            <origin xyz="0.0 -0.17891535260447497 0.0" rpy="0 0 0"/>
            <geometry>
                <box size="0.2330897974952698 0.35783070520894994 0.3147667609680614" />
            </geometry>
        </collision>
    </link>
    <joint name="Cube2_Cube3" type="revolute">
       <parent link="Cube2"/>
       <child  link="Cube3"/>
       <origin rpy="0 0 0" xyz="0.0 -0.17891535260447497 -0.1573833804840307" />
     <axis xyz="0 1 0"/>
       <limit effort="0.0" lower="-3.14159" upper="3.14159" velocity="0.0"/>
    </joint>
    <link name="Cube3">
        <inertial>
            <origin xyz="0.0 0.0 -0.12475577792441286" rpy="0 0 0"/>
            <mass value="1" />
            <inertia ixx="100" ixy="0" ixz="0" iyy="100" iyz="0" izz="100" />
        </inertial>
        <visual>
            <origin xyz="0.0 0.0 -0.12475577792441286" rpy="0 0 0"/>
            <geometry>
                <box size="0.2071284014535964 0.2045384180145826 0.24951155584882573" />
            </geometry>
            <material name="Green">
                <color rgba="0.1 0.9 0.1 0.9"/>
            </material>
        </visual>
        <collision>
            <origin xyz="0.0 0.0 -0.12475577792441286" rpy="0 0 0"/>
            <geometry>
                <box size="0.2071284014535964 0.2045384180145826 0.24951155584882573" />
            </geometry>
        </collision>
    </link>
    <joint name="Cube3_Cube4" type="revolute">
       <parent link="Cube3"/>
       <child  link="Cube4"/>
       <origin rpy="0 0 0" xyz="0.0 -0.1022692090072913 -0.12475577792441286" />
     <axis xyz="0 1 0"/>
       <limit effort="0.0" lower="-3.14159" upper="3.14159" velocity="0.0"/>
    </joint>
    <link name="Cube4">
        <inertial>
            <origin xyz="0.0 -0.10224809075866978 0.0" rpy="0 0 0"/>
            <mass value="1" />
            <inertia ixx="100" ixy="0" ixz="0" iyy="100" iyz="0" izz="100" />
        </inertial>
        <visual>
            <origin xyz="0.0 -0.10224809075866978 0.0" rpy="0 0 0"/>
            <geometry>
                <box size="0.2051391406605549 0.20449618151733956 0.2281474025343521" />
            </geometry>
            <material name="Blue">
                <color rgba="0.1 0.2 0.9 0.9"/>
            </material>
        </visual>
        <collision>
            <origin xyz="0.0 -0.10224809075866978 0.0" rpy="0 0 0"/>
            <geometry>
                <box size="0.2051391406605549 0.20449618151733956 0.2281474025343521" />
            </geometry>
        </collision>
    </link>
    <joint name="Cube0_Cube5" type="revolute">
       <parent link="Cube0"/>
       <child  link="Cube5"/>
       <origin rpy="0 0 0" xyz="0.0 0.5749689440638529 3" />
     <axis xyz="0 1 0"/>
       <limit effort="0.0" lower="-3.14159" upper="3.14159" velocity="0.0"/>
    </joint>
    <link name="Cube5">
        <inertial>
            <origin xyz="0.0 0.10193963042420441 0.0" rpy="0 0 0"/>
            <mass value="1" />
            <inertia ixx="100" ixy="0" ixz="0" iyy="100" iyz="0" izz="100" />
        </inertial>
        <visual>
            <origin xyz="0.0 0.10193963042420441 0.0" rpy="0 0 0"/>
            <geometry>
                <box size="0.2038705112191872 0.20387926084840882 0.22678881682032553" />
            </geometry>
            <material name="Green">
                <color rgba="0.1 0.9 0.1 0.9"/>
            </material>
        </visual>
        <collision>
            <origin xyz="0.0 0.10193963042420441 0.0" rpy="0 0 0"/>
            <geometry>
                <box size="0.2038705112191872 0.20387926084840882 0.22678881682032553" />
            </geometry>
        </collision>
    </link>
    <joint name="Cube5_Cube6" type="revolute">
       <parent link="Cube5"/>
       <child  link="Cube6"/>
       <origin rpy="0 0 0" xyz="0.0 0.20387926084840882 0.0" />
     <axis xyz="0 1 0"/>
       <limit effort="0.0" lower="-3.14159" upper="3.14159" velocity="0.0"/>
    </joint>
    <link name="Cube6">
        <inertial>
            <origin xyz="0.0 0.10032152087364574 0.0" rpy="0 0 0"/>
            <mass value="1" />
            <inertia ixx="100" ixy="0" ixz="0" iyy="100" iyz="0" izz="100" />
        </inertial>
        <visual>
            <origin xyz="0.0 0.10032152087364574 0.0" rpy="0 0 0"/>
            <geometry>
                <box size="0.20257323337283592 0.20064304174729147 0.2027091076707052" />
            </geometry>
            <material name="Green">
                <color rgba="0.1 0.9 0.1 0.9"/>
            </material>
        </visual>
        <collision>
            <origin xyz="0.0 0.10032152087364574 0.0" rpy="0 0 0"/>
            <geometry>
                <box size="0.20257323337283592 0.20064304174729147 0.2027091076707052" />
            </geometry>
        </collision>
    </link>
    <joint name="Cube0_Cube7" type="revolute">
       <parent link="Cube0"/>
       <child  link="Cube7"/>
       <origin rpy="0 0 0" xyz="0.15086762465812814 0.0 3" />
     <axis xyz="0 1 0"/>
       <limit effort="0.0" lower="-3.14159" upper="3.14159" velocity="0.0"/>
    </joint>
    <link name="Cube7">
        <inertial>
            <origin xyz="0.16672659917506427 0.0 0.0" rpy="0 0 0"/>
            <mass value="1" />
            <inertia ixx="100" ixy="0" ixz="0" iyy="100" iyz="0" izz="100" />
        </inertial>
        <visual>
            <origin xyz="0.16672659917506427 0.0 0.0" rpy="0 0 0"/>
            <geometry>
                <box size="0.33345319835012854 1.0195205142971724 1.4726612171863405" />
            </geometry>
            <material name="Blue">
                <color rgba="0.1 0.2 0.9 0.9"/>
            </material>
        </visual>
        <collision>
            <origin xyz="0.16672659917506427 0.0 0.0" rpy="0 0 0"/>
            <geometry>
                <box size="0.33345319835012854 1.0195205142971724 1.4726612171863405" />
            </geometry>
        </collision>
    </link>
    <joint name="Cube7_Cube8" type="revolute">
       <parent link="Cube7"/>
       <child  link="Cube8"/>
       <origin rpy="0 0 0" xyz="0.16672659917506427 -0.5097602571485862 0.0" />
     <axis xyz="0 1 0"/>
       <limit effort="0.0" lower="-3.14159" upper="3.14159" velocity="0.0"/>
    </joint>
    <link name="Cube8">
        <inertial>
            <origin xyz="0.0 -0.33485684809829114 0.0" rpy="0 0 0"/>
            <mass value="1" />
            <inertia ixx="100" ixy="0" ixz="0" iyy="100" iyz="0" izz="100" />
        </inertial>
        <visual>
            <origin xyz="0.0 -0.33485684809829114 0.0" rpy="0 0 0"/>
            <geometry>
                <box size="0.31997294635743173 0.6697136961965823 1.0938645006619618" />
            </geometry>
            <material name="Green">
                <color rgba="0.1 0.9 0.1 0.9"/>
            </material>
        </visual>
        <collision>
            <origin xyz="0.0 -0.33485684809829114 0.0" rpy="0 0 0"/>
            <geometry>
                <box size="0.31997294635743173 0.6697136961965823 1.0938645006619618" />
            </geometry>
        </collision>
    </link>
    <joint name="Cube8_Cube9" type="revolute">
       <parent link="Cube8"/>
       <child  link="Cube9"/>
       <origin rpy="0 0 0" xyz="0.0 -0.33485684809829114 -0.5469322503309809" />
     <axis xyz="0 1 0"/>
       <limit effort="0.0" lower="-3.14159" upper="3.14159" velocity="0.0"/>
    </joint>
    <link name="Cube9">
        <inertial>
            <origin xyz="0.0 0.0 -0.21932950858546033" rpy="0 0 0"/>
            <mass value="1" />
            <inertia ixx="100" ixy="0" ixz="0" iyy="100" iyz="0" izz="100" />
        </inertial>
        <visual>
            <origin xyz="0.0 0.0 -0.21932950858546033" rpy="0 0 0"/>
            <geometry>
                <box size="0.317743335549183 0.6104663571604139 0.43865901717092065" />
            </geometry>
            <material name="Blue">
                <color rgba="0.1 0.2 0.9 0.9"/>
            </material>
        </visual>
        <collision>
            <origin xyz="0.0 0.0 -0.21932950858546033" rpy="0 0 0"/>
            <geometry>
                <box size="0.317743335549183 0.6104663571604139 0.43865901717092065" />
            </geometry>
        </collision>
    </link>
    <joint name="Cube9_Cube10" type="revolute">
       <parent link="Cube9"/>
       <child  link="Cube10"/>
       <origin rpy="0 0 0" xyz="0.0 0.0 -0.43865901717092065" />
     <axis xyz="0 1 0"/>
       <limit effort="0.0" lower="-3.14159" upper="3.14159" velocity="0.0"/>
    </joint>
    <link name="Cube10">
        <inertial>
            <origin xyz="0.0 0.0 -0.19397859277107976" rpy="0 0 0"/>
            <mass value="1" />
            <inertia ixx="100" ixy="0" ixz="0" iyy="100" iyz="0" izz="100" />
        </inertial>
        <visual>
            <origin xyz="0.0 0.0 -0.19397859277107976" rpy="0 0 0"/>
            <geometry>
                <box size="0.24515534118506274 0.43793028801041534 0.3879571855421595" />
            </geometry>
            <material name="Blue">
                <color rgba="0.1 0.2 0.9 0.9"/>
            </material>
        </visual>
        <collision>
            <origin xyz="0.0 0.0 -0.19397859277107976" rpy="0 0 0"/>
            <geometry>
                <box size="0.24515534118506274 0.43793028801041534 0.3879571855421595" />
            </geometry>
        </collision>
    </link>
    <joint name="Cube7_Cube11" type="revolute">
       <parent link="Cube7"/>
       <child  link="Cube11"/>
       <origin rpy="0 0 0" xyz="-0.16672659917506427 0.5097602571485862 0.0" />
     <axis xyz="0 1 0"/>
       <limit effort="0.0" lower="-3.14159" upper="3.14159" velocity="0.0"/>
    </joint>
    <link name="Cube11">
        <inertial>
            <origin xyz="0.0 0.19763344451753292 0.0" rpy="0 0 0"/>
            <mass value="1" />
            <inertia ixx="100" ixy="0" ixz="0" iyy="100" iyz="0" izz="100" />
        </inertial>
        <visual>
            <origin xyz="0.0 0.19763344451753292 0.0" rpy="0 0 0"/>
            <geometry>
                <box size="0.21179066739673846 0.39526688903506585 0.35040553551073245" />
            </geometry>
            <material name="Green">
                <color rgba="0.1 0.9 0.1 0.9"/>
            </material>
        </visual>
        <collision>
            <origin xyz="0.0 0.19763344451753292 0.0" rpy="0 0 0"/>
            <geometry>
                <box size="0.21179066739673846 0.39526688903506585 0.35040553551073245" />
            </geometry>
        </collision>
    </link>
    <joint name="Cube11_Cube12" type="revolute">
       <parent link="Cube11"/>
       <child  link="Cube12"/>
       <origin rpy="0 0 0" xyz="0.0 0.19763344451753292 -0.17520276775536622" />
     <axis xyz="0 1 0"/>
       <limit effort="0.0" lower="-3.14159" upper="3.14159" velocity="0.0"/>
    </joint>
    <link name="Cube12">
        <inertial>
            <origin xyz="0.0 0.0 -0.1513252008673278" rpy="0 0 0"/>
            <mass value="1" />
            <inertia ixx="100" ixy="0" ixz="0" iyy="100" iyz="0" izz="100" />
        </inertial>
        <visual>
            <origin xyz="0.0 0.0 -0.1513252008673278" rpy="0 0 0"/>
            <geometry>
                <box size="0.2007839871495418 0.27015081469609736 0.3026504017346556" />
            </geometry>
            <material name="Green">
                <color rgba="0.1 0.9 0.1 0.9"/>
            </material>
        </visual>
        <collision>
            <origin xyz="0.0 0.0 -0.1513252008673278" rpy="0 0 0"/>
            <geometry>
                <box size="0.2007839871495418 0.27015081469609736 0.3026504017346556" />
            </geometry>
        </collision>
    </link>
    <joint name="Cube12_Cube13" type="revolute">
       <parent link="Cube12"/>
       <child  link="Cube13"/>
       <origin rpy="0 0 0" xyz="0.0 0.0 -0.3026504017346556" />
     <axis xyz="0 1 0"/>
       <limit effort="0.0" lower="-3.14159" upper="3.14159" velocity="0.0"/>
    </joint>
    <link name="Cube13">
        <inertial>
            <origin xyz="0.0 0.0 -0.14430302396213263" rpy="0 0 0"/>
            <mass value="1" />
            <inertia ixx="100" ixy="0" ixz="0" iyy="100" iyz="0" izz="100" />
        </inertial>
        <visual>
            <origin xyz="0.0 0.0 -0.14430302396213263" rpy="0 0 0"/>
            <geometry>
                <box size="0.20074829454977056 0.25526976966486653 0.28860604792426525" />
            </geometry>
            <material name="Green">
                <color rgba="0.1 0.9 0.1 0.9"/>
            </material>
        </visual>
        <collision>
            <origin xyz="0.0 0.0 -0.14430302396213263" rpy="0 0 0"/>
            <geometry>
                <box size="0.20074829454977056 0.25526976966486653 0.28860604792426525" />
            </geometry>
        </collision>
    </link>
    <joint name="Cube7_Cube14" type="revolute">
       <parent link="Cube7"/>
       <child  link="Cube14"/>
       <origin rpy="0 0 0" xyz="0.33345319835012854 0.0 0.0" />
     <axis xyz="0 1 0"/>
       <limit effort="0.0" lower="-3.14159" upper="3.14159" velocity="0.0"/>
    </joint>
    <link name="Cube14">
        <inertial>
            <origin xyz="0.6948946887006949 0.0 0.0" rpy="0 0 0"/>
            <mass value="1" />
            <inertia ixx="100" ixy="0" ixz="0" iyy="100" iyz="0" izz="100" />
        </inertial>
        <visual>
            <origin xyz="0.6948946887006949 0.0 0.0" rpy="0 0 0"/>
            <geometry>
                <box size="1.3897893774013899 1.2702127336510136 0.814065042075846" />
            </geometry>
            <material name="Blue">
                <color rgba="0.1 0.2 0.9 0.9"/>
            </material>
        </visual>
        <collision>
            <origin xyz="0.6948946887006949 0.0 0.0" rpy="0 0 0"/>
            <geometry>
                <box size="1.3897893774013899 1.2702127336510136 0.814065042075846" />
            </geometry>
        </collision>
    </link>
</robot>