<robot name = "robot">
    <link name="Cube0">
        <inertial>
            <origin xyz="0.0 0.0 0.8571598198529593" rpy="0 0 0"/>
            <mass value="1" />
            <inertia ixx="100" ixy="0" ixz="0" iyy="100" iyz="0" izz="100" />
        </inertial>
        <visual>
            <origin xyz="0.0 0.0 0.8571598198529593" rpy="0 0 0"/>
            <geometry>
                <box size="0.46246486301151224 1.3617453981678458 0.8571598198529593" />
            </geometry>
            <material name="Green">
                <color rgba="0.1 0.9 0.1 1.0"/>
            </material>
        </visual>
        <collision>
            <origin xyz="0.0 0.0 0.8571598198529593" rpy="0 0 0"/>
            <geometry>
                <box size="0.46246486301151224 1.3617453981678458 0.8571598198529593" />
            </geometry>
        </collision>
    </link>
    <joint name="Cube0_Cube1" type="revolute">
       <parent link="Cube0"/>
       <child  link="Cube1"/>
       <origin rpy="0 0 0" xyz="0.11561621575287806 0.0 0.42857990992647965" />
     <axis xyz="0 1 0"/>
       <limit effort="0.0" lower="-3.14159" upper="3.14159" velocity="0.0"/>
    </joint>
    <link name="Cube1">
        <inertial>
            <origin xyz="0.8536127377186705 0.0 0.42857990992647965" rpy="0 0 0"/>
            <mass value="1" />
            <inertia ixx="100" ixy="0" ixz="0" iyy="100" iyz="0" izz="100" />
        </inertial>
        <visual>
            <origin xyz="0.8536127377186705 0.0 0.42857990992647965" rpy="0 0 0"/>
            <geometry>
                <box size="1.475993043931585 0.8116661443237474 0.4820237752274309" />
            </geometry>
            <material name="Green">
                <color rgba="0.1 0.9 0.1 1.0"/>
            </material>
        </visual>
        <collision>
            <origin xyz="0.8536127377186705 0.0 0.42857990992647965" rpy="0 0 0"/>
            <geometry>
                <box size="1.475993043931585 0.8116661443237474 0.4820237752274309" />
            </geometry>
        </collision>
    </link>
    <joint name="Cube1_Cube2" type="revolute">
       <parent link="Cube1"/>
       <child  link="Cube2"/>
       <origin rpy="0 0 0" xyz="0.7379965219657925 0.0 0.24101188761371545" />
     <axis xyz="0 1 0"/>
       <limit effort="0.0" lower="-3.14159" upper="3.14159" velocity="0.0"/>
    </joint>
    <link name="Cube2">
        <inertial>
            <origin xyz="0.5895227626855647 0.0 0.24101188761371545" rpy="0 0 0"/>
            <mass value="1" />
            <inertia ixx="100" ixy="0" ixz="0" iyy="100" iyz="0" izz="100" />
        </inertial>
        <visual>
            <origin xyz="0.5895227626855647 0.0 0.24101188761371545" rpy="0 0 0"/>
            <geometry>
                <box size="0.2205245017026685 0.6105413304251394 0.7685526998780972" />
            </geometry>
            <material name="Green">
                <color rgba="0.1 0.9 0.1 1.0"/>
            </material>
        </visual>
        <collision>
            <origin xyz="0.5895227626855647 0.0 0.24101188761371545" rpy="0 0 0"/>
            <geometry>
                <box size="0.2205245017026685 0.6105413304251394 0.7685526998780972" />
            </geometry>
        </collision>
    </link>
    <joint name="Cube2_Cube3" type="revolute">
       <parent link="Cube2"/>
       <child  link="Cube3"/>
       <origin rpy="0 0 0" xyz="0.11026225085133425 0.0 0.3842763499390486" />
     <axis xyz="0 1 0"/>
       <limit effort="0.0" lower="-3.14159" upper="3.14159" velocity="0.0"/>
    </joint>
    <link name="Cube3">
        <inertial>
            <origin xyz="1.0295569028385365 0.0 0.3842763499390486" rpy="0 0 0"/>
            <mass value="1" />
            <inertia ixx="100" ixy="0" ixz="0" iyy="100" iyz="0" izz="100" />
        </inertial>
        <visual>
            <origin xyz="1.0295569028385365 0.0 0.3842763499390486" rpy="0 0 0"/>
            <geometry>
                <box size="0.9744257774128693 1.3327790679724334 0.36221691924218447" />
            </geometry>
            <material name="Blue">
                <color rgba="0.1 0.2 0.9 0.9"/>
            </material>
        </visual>
        <collision>
            <origin xyz="1.0295569028385365 0.0 0.3842763499390486" rpy="0 0 0"/>
            <geometry>
                <box size="0.9744257774128693 1.3327790679724334 0.36221691924218447" />
            </geometry>
        </collision>
    </link>
    <joint name="Cube3_Cube4" type="revolute">
       <parent link="Cube3"/>
       <child  link="Cube4"/>
       <origin rpy="0 0 0" xyz="0.48721288870643464 0.0 0.18110845962109223" />
     <axis xyz="0 1 0"/>
       <limit effort="0.0" lower="-3.14159" upper="3.14159" velocity="0.0"/>
    </joint>
    <link name="Cube4">
        <inertial>
            <origin xyz="1.3685278386649116 0.0 0.18110845962109223" rpy="0 0 0"/>
            <mass value="1" />
            <inertia ixx="100" ixy="0" ixz="0" iyy="100" iyz="0" izz="100" />
        </inertial>
        <visual>
            <origin xyz="1.3685278386649116 0.0 0.18110845962109223" rpy="0 0 0"/>
            <geometry>
                <box size="1.1249213943116942 1.0003427339314683 1.4653957942469666" />
            </geometry>
            <material name="Blue">
                <color rgba="0.1 0.2 0.9 0.9"/>
            </material>
        </visual>
        <collision>
            <origin xyz="1.3685278386649116 0.0 0.18110845962109223" rpy="0 0 0"/>
            <geometry>
                <box size="1.1249213943116942 1.0003427339314683 1.4653957942469666" />
            </geometry>
        </collision>
    </link>
    <joint name="Cube4_Cube5" type="revolute">
       <parent link="Cube4"/>
       <child  link="Cube5"/>
       <origin rpy="0 0 0" xyz="0.5624606971558471 0.0 0.7326978971234833" />
     <axis xyz="0 1 0"/>
       <limit effort="0.0" lower="-3.14159" upper="3.14159" velocity="0.0"/>
    </joint>
    <link name="Cube5">
        <inertial>
            <origin xyz="1.3419596443776969 0.0 0.7326978971234833" rpy="0 0 0"/>
            <mass value="1" />
            <inertia ixx="100" ixy="0" ixz="0" iyy="100" iyz="0" izz="100" />
        </inertial>
        <visual>
            <origin xyz="1.3419596443776969 0.0 0.7326978971234833" rpy="0 0 0"/>
            <geometry>
                <box size="1.0607292957997734 0.5251404192899074 0.2184016551827268" />
            </geometry>
            <material name="Blue">
                <color rgba="0.1 0.2 0.9 0.9"/>
            </material>
        </visual>
        <collision>
            <origin xyz="1.3419596443776969 0.0 0.7326978971234833" rpy="0 0 0"/>
            <geometry>
                <box size="1.0607292957997734 0.5251404192899074 0.2184016551827268" />
            </geometry>
        </collision>
    </link>
    <joint name="Cube5_Cube6" type="revolute">
       <parent link="Cube5"/>
       <child  link="Cube6"/>
       <origin rpy="0 0 0" xyz="0.5303646478998867 0.0 0.1092008275913634" />
     <axis xyz="0 1 0"/>
       <limit effort="0.0" lower="-3.14159" upper="3.14159" velocity="0.0"/>
    </joint>
    <link name="Cube6">
        <inertial>
            <origin xyz="1.5852360867711417 0.0 0.1092008275913634" rpy="0 0 0"/>
            <mass value="1" />
            <inertia ixx="100" ixy="0" ixz="0" iyy="100" iyz="0" izz="100" />
        </inertial>
        <visual>
            <origin xyz="1.5852360867711417 0.0 0.1092008275913634" rpy="0 0 0"/>
            <geometry>
                <box size="1.3200537628211984 0.8045383431858057 0.38505367828217585" />
            </geometry>
            <material name="Blue">
                <color rgba="0.1 0.2 0.9 0.9"/>
            </material>
        </visual>
        <collision>
            <origin xyz="1.5852360867711417 0.0 0.1092008275913634" rpy="0 0 0"/>
            <geometry>
                <box size="1.3200537628211984 0.8045383431858057 0.38505367828217585" />
            </geometry>
        </collision>
    </link>
</robot>