<robot name = "robot">
    <link name="Cube0">
        <inertial>
            <origin xyz="0.0 0.0 1.7872907515699616" rpy="0 0 0"/>
            <mass value="1" />
            <inertia ixx="100" ixy="0" ixz="0" iyy="100" iyz="0" izz="100" />
        </inertial>
        <visual>
            <origin xyz="0.0 0.0 1.7872907515699616" rpy="0 0 0"/>
            <geometry>
                <box size="0.5668012223169285 1.1625662692443939 1.7872907515699616" />
            </geometry>
            <material name="Cyan">
                <color rgba="0.8 0.2 0.8 1.0"/>
            </material>
        </visual>
        <collision>
            <origin xyz="0.0 0.0 1.7872907515699616" rpy="0 0 0"/>
            <geometry>
                <box size="0.5668012223169285 1.1625662692443939 1.7872907515699616" />
            </geometry>
        </collision>
    </link>
    <joint name="Cube0_Cube1" type="revolute">
       <parent link="Cube0"/>
       <child  link="Cube1"/>
       <origin rpy="0 0 0" xyz="0.14170030557923213 0.0 0.8936453757849808" />
     <axis xyz="0 1 0"/>
       <limit effort="0.0" lower="-3.14159" upper="3.14159" velocity="0.0"/>
    </joint>
    <link name="Cube1">
        <inertial>
            <origin xyz="0.6589317010506583 0.0 0.8936453757849808" rpy="0 0 0"/>
            <mass value="1" />
            <inertia ixx="100" ixy="0" ixz="0" iyy="100" iyz="0" izz="100" />
        </inertial>
        <visual>
            <origin xyz="0.6589317010506583 0.0 0.8936453757849808" rpy="0 0 0"/>
            <geometry>
                <box size="1.0344627909428525 1.7002043153528659 0.7150804436725717" />
            </geometry>
            <material name="Cyan">
                <color rgba="0.8 0.2 0.8 1.0"/>
            </material>
        </visual>
        <collision>
            <origin xyz="0.6589317010506583 0.0 0.8936453757849808" rpy="0 0 0"/>
            <geometry>
                <box size="1.0344627909428525 1.7002043153528659 0.7150804436725717" />
            </geometry>
        </collision>
    </link>
</robot>