<robot name = "robot">
    <link name="Cube0">
        <inertial>
            <origin xyz="0.0 0.0 3" rpy="0 0 0"/>
            <mass value="1" />
            <inertia ixx="100" ixy="0" ixz="0" iyy="100" iyz="0" izz="100" />
        </inertial>
        <visual>
            <origin xyz="0.0 0.0 3" rpy="0 0 0"/>
            <geometry>
                <box size="0.2708690656106623 0.8097915477163535 1.477676169791921" />
            </geometry>
            <material name="Blue">
                <color rgba="0.1 0.2 0.9 0.9"/>
            </material>
        </visual>
        <collision>
            <origin xyz="0.0 0.0 3" rpy="0 0 0"/>
            <geometry>
                <box size="0.2708690656106623 0.8097915477163535 1.477676169791921" />
            </geometry>
        </collision>
    </link>
    <joint name="Cube0_Cube1" type="revolute">
       <parent link="Cube0"/>
       <child  link="Cube1"/>
       <origin rpy="0 0 0" xyz="0.0 -0.40489577385817677 3" />
     <axis xyz="0 1 0"/>
       <limit effort="0.0" lower="-3.14159" upper="3.14159" velocity="0.0"/>
    </joint>
    <link name="Cube1">
        <inertial>
            <origin xyz="0.0 -0.17540588141072497 0.0" rpy="0 0 0"/>
            <mass value="1" />
            <inertia ixx="100" ixy="0" ixz="0" iyy="100" iyz="0" izz="100" />
        </inertial>
        <visual>
            <origin xyz="0.0 -0.17540588141072497 0.0" rpy="0 0 0"/>
            <geometry>
                <box size="0.24502885576298045 0.35081176282144994 1.074629089984777" />
            </geometry>
            <material name="Green">
                <color rgba="0.1 0.9 0.1 0.9"/>
            </material>
        </visual>
        <collision>
            <origin xyz="0.0 -0.17540588141072497 0.0" rpy="0 0 0"/>
            <geometry>
                <box size="0.24502885576298045 0.35081176282144994 1.074629089984777" />
            </geometry>
        </collision>
    </link>
    <joint name="Cube1_Cube2" type="revolute">
       <parent link="Cube1"/>
       <child  link="Cube2"/>
       <origin rpy="0 0 0" xyz="0.0 -0.35081176282144994 0.0" />
     <axis xyz="0 1 0"/>
       <limit effort="0.0" lower="-3.14159" upper="3.14159" velocity="0.0"/>
    </joint>
    <link name="Cube2">
        <inertial>
            <origin xyz="0.0 -0.11408521494262777 0.0" rpy="0 0 0"/>
            <mass value="1" />
            <inertia ixx="100" ixy="0" ixz="0" iyy="100" iyz="0" izz="100" />
        </inertial>
        <visual>
            <origin xyz="0.0 -0.11408521494262777 0.0" rpy="0 0 0"/>
            <geometry>
                <box size="0.23973667168073529 0.22817042988525554 0.3676774070821345" />
            </geometry>
            <material name="Blue">
                <color rgba="0.1 0.2 0.9 0.9"/>
            </material>
        </visual>
        <collision>
            <origin xyz="0.0 -0.11408521494262777 0.0" rpy="0 0 0"/>
            <geometry>
                <box size="0.23973667168073529 0.22817042988525554 0.3676774070821345" />
            </geometry>
        </collision>
    </link>
    <joint name="Cube0_Cube3" type="revolute">
       <parent link="Cube0"/>
       <child  link="Cube3"/>
       <origin rpy="0 0 0" xyz="0.0 0.40489577385817677 3" />
     <axis xyz="0 1 0"/>
       <limit effort="0.0" lower="-3.14159" upper="3.14159" velocity="0.0"/>
    </joint>
    <link name="Cube3">
        <inertial>
            <origin xyz="0.0 0.10615246035360494 0.0" rpy="0 0 0"/>
            <mass value="1" />
            <inertia ixx="100" ixy="0" ixz="0" iyy="100" iyz="0" izz="100" />
        </inertial>
        <visual>
            <origin xyz="0.0 0.10615246035360494 0.0" rpy="0 0 0"/>
            <geometry>
                <box size="0.20105800404014323 0.21230492070720988 0.2469586394726287" />
            </geometry>
            <material name="Blue">
                <color rgba="0.1 0.2 0.9 0.9"/>
            </material>
        </visual>
        <collision>
            <origin xyz="0.0 0.10615246035360494 0.0" rpy="0 0 0"/>
            <geometry>
                <box size="0.20105800404014323 0.21230492070720988 0.2469586394726287" />
            </geometry>
        </collision>
    </link>
    <joint name="Cube3_Cube4" type="revolute">
       <parent link="Cube3"/>
       <child  link="Cube4"/>
       <origin rpy="0 0 0" xyz="0.0 0.21230492070720988 0.0" />
     <axis xyz="0 1 0"/>
       <limit effort="0.0" lower="-3.14159" upper="3.14159" velocity="0.0"/>
    </joint>
    <link name="Cube4">
        <inertial>
            <origin xyz="0.0 0.10295997420726213 0.0" rpy="0 0 0"/>
            <mass value="1" />
            <inertia ixx="100" ixy="0" ixz="0" iyy="100" iyz="0" izz="100" />
        </inertial>
        <visual>
            <origin xyz="0.0 0.10295997420726213 0.0" rpy="0 0 0"/>
            <geometry>
                <box size="0.20019219040988445 0.20591994841452427 0.24479482030582733" />
            </geometry>
            <material name="Green">
                <color rgba="0.1 0.9 0.1 0.9"/>
            </material>
        </visual>
        <collision>
            <origin xyz="0.0 0.10295997420726213 0.0" rpy="0 0 0"/>
            <geometry>
                <box size="0.20019219040988445 0.20591994841452427 0.24479482030582733" />
            </geometry>
        </collision>
    </link>
    <joint name="Cube4_Cube5" type="revolute">
       <parent link="Cube4"/>
       <child  link="Cube5"/>
       <origin rpy="0 0 0" xyz="0.0 0.20591994841452427 0.0" />
     <axis xyz="0 1 0"/>
       <limit effort="0.0" lower="-3.14159" upper="3.14159" velocity="0.0"/>
    </joint>
    <link name="Cube5">
        <inertial>
            <origin xyz="0.0 0.10085687703671278 0.0" rpy="0 0 0"/>
            <mass value="1" />
            <inertia ixx="100" ixy="0" ixz="0" iyy="100" iyz="0" izz="100" />
        </inertial>
        <visual>
            <origin xyz="0.0 0.10085687703671278 0.0" rpy="0 0 0"/>
            <geometry>
                <box size="0.20013086451897838 0.20171375407342557 0.22514630675675068" />
            </geometry>
            <material name="Green">
                <color rgba="0.1 0.9 0.1 0.9"/>
            </material>
        </visual>
        <collision>
            <origin xyz="0.0 0.10085687703671278 0.0" rpy="0 0 0"/>
            <geometry>
                <box size="0.20013086451897838 0.20171375407342557 0.22514630675675068" />
            </geometry>
        </collision>
    </link>
    <joint name="Cube0_Cube6" type="revolute">
       <parent link="Cube0"/>
       <child  link="Cube6"/>
       <origin rpy="0 0 0" xyz="0.13543453280533116 0.0 3" />
     <axis xyz="0 1 0"/>
       <limit effort="0.0" lower="-3.14159" upper="3.14159" velocity="0.0"/>
    </joint>
    <link name="Cube6">
        <inertial>
            <origin xyz="0.31859656330231095 0.0 0.0" rpy="0 0 0"/>
            <mass value="1" />
            <inertia ixx="100" ixy="0" ixz="0" iyy="100" iyz="0" izz="100" />
        </inertial>
        <visual>
            <origin xyz="0.31859656330231095 0.0 0.0" rpy="0 0 0"/>
            <geometry>
                <box size="0.6371931266046219 0.33463990325065684 0.7257770255288258" />
            </geometry>
            <material name="Blue">
                <color rgba="0.1 0.2 0.9 0.9"/>
            </material>
        </visual>
        <collision>
            <origin xyz="0.31859656330231095 0.0 0.0" rpy="0 0 0"/>
            <geometry>
                <box size="0.6371931266046219 0.33463990325065684 0.7257770255288258" />
            </geometry>
        </collision>
    </link>
</robot>