<robot name = "robot">
    <link name="Cube0">
        <inertial>
            <origin xyz="0.0 0.0 0.5745854030037043" rpy="0 0 0"/>
            <mass value="1" />
            <inertia ixx="100" ixy="0" ixz="0" iyy="100" iyz="0" izz="100" />
        </inertial>
        <visual>
            <origin xyz="0.0 0.0 0.5745854030037043" rpy="0 0 0"/>
            <geometry>
                <box size="0.4245906286042044 0.4081494047609957 0.5745854030037043" />
            </geometry>
            <material name="Blue">
                <color rgba="0.1 0.2 0.9 0.9"/>
            </material>
        </visual>
        <collision>
            <origin xyz="0.0 0.0 0.5745854030037043" rpy="0 0 0"/>
            <geometry>
                <box size="0.4245906286042044 0.4081494047609957 0.5745854030037043" />
            </geometry>
        </collision>
    </link>
    <joint name="Cube0_Cube1" type="revolute">
       <parent link="Cube0"/>
       <child  link="Cube1"/>
       <origin rpy="0 0 0" xyz="0.2122953143021022 0.0 0.5745854030037043" />
     <axis xyz="0 1 0"/>
       <limit effort="0.0" lower="-3.14159" upper="3.14159" velocity="0.0"/>
    </joint>
    <link name="Cube1">
        <inertial>
            <origin xyz="0.22611410974356957 0.0 0.0" rpy="0 0 0"/>
            <mass value="1" />
            <inertia ixx="100" ixy="0" ixz="0" iyy="100" iyz="0" izz="100" />
        </inertial>
        <visual>
            <origin xyz="0.22611410974356957 0.0 0.0" rpy="0 0 0"/>
            <geometry>
                <box size="0.45222821948713915 1.0971783421744834 0.5773281728999081" />
            </geometry>
            <material name="Blue">
                <color rgba="0.1 0.2 0.9 0.9"/>
            </material>
        </visual>
        <collision>
            <origin xyz="0.22611410974356957 0.0 0.0" rpy="0 0 0"/>
            <geometry>
                <box size="0.45222821948713915 1.0971783421744834 0.5773281728999081" />
            </geometry>
        </collision>
    </link>
    <joint name="Cube1_Cube2" type="revolute">
       <parent link="Cube1"/>
       <child  link="Cube2"/>
       <origin rpy="0 0 0" xyz="0.45222821948713915 0.0 0.0" />
     <axis xyz="0 1 0"/>
       <limit effort="0.0" lower="-3.14159" upper="3.14159" velocity="0.0"/>
    </joint>
    <link name="Cube2">
        <inertial>
            <origin xyz="0.3762333086243743 0.0 0.0" rpy="0 0 0"/>
            <mass value="1" />
            <inertia ixx="100" ixy="0" ixz="0" iyy="100" iyz="0" izz="100" />
        </inertial>
        <visual>
            <origin xyz="0.3762333086243743 0.0 0.0" rpy="0 0 0"/>
            <geometry>
                <box size="0.7524666172487486 1.4561803317211874 1.488488966020785" />
            </geometry>
            <material name="Blue">
                <color rgba="0.1 0.2 0.9 0.9"/>
            </material>
        </visual>
        <collision>
            <origin xyz="0.3762333086243743 0.0 0.0" rpy="0 0 0"/>
            <geometry>
                <box size="0.7524666172487486 1.4561803317211874 1.488488966020785" />
            </geometry>
        </collision>
    </link>
    <joint name="Cube2_Cube3" type="revolute">
       <parent link="Cube2"/>
       <child  link="Cube3"/>
       <origin rpy="0 0 0" xyz="0.7524666172487486 0.0 0.0" />
     <axis xyz="0 1 0"/>
       <limit effort="0.0" lower="-3.14159" upper="3.14159" velocity="0.0"/>
    </joint>
    <link name="Cube3">
        <inertial>
            <origin xyz="0.5150159667888319 0.0 0.0" rpy="0 0 0"/>
            <mass value="1" />
            <inertia ixx="100" ixy="0" ixz="0" iyy="100" iyz="0" izz="100" />
        </inertial>
        <visual>
            <origin xyz="0.5150159667888319 0.0 0.0" rpy="0 0 0"/>
            <geometry>
                <box size="1.0300319335776638 1.0324790929476233 0.6238794634484706" />
            </geometry>
            <material name="Blue">
                <color rgba="0.1 0.2 0.9 0.9"/>
            </material>
        </visual>
        <collision>
            <origin xyz="0.5150159667888319 0.0 0.0" rpy="0 0 0"/>
            <geometry>
                <box size="1.0300319335776638 1.0324790929476233 0.6238794634484706" />
            </geometry>
        </collision>
    </link>
    <joint name="Cube3_Cube4" type="revolute">
       <parent link="Cube3"/>
       <child  link="Cube4"/>
       <origin rpy="0 0 0" xyz="1.0300319335776638 0.0 0.0" />
     <axis xyz="0 1 0"/>
       <limit effort="0.0" lower="-3.14159" upper="3.14159" velocity="0.0"/>
    </joint>
    <link name="Cube4">
        <inertial>
            <origin xyz="0.44546336148632404 0.0 0.0" rpy="0 0 0"/>
            <mass value="1" />
            <inertia ixx="100" ixy="0" ixz="0" iyy="100" iyz="0" izz="100" />
        </inertial>
        <visual>
            <origin xyz="0.44546336148632404 0.0 0.0" rpy="0 0 0"/>
            <geometry>
                <box size="0.8909267229726481 0.7448161818447459 0.6804117718113273" />
            </geometry>
            <material name="Blue">
                <color rgba="0.1 0.2 0.9 0.9"/>
            </material>
        </visual>
        <collision>
            <origin xyz="0.44546336148632404 0.0 0.0" rpy="0 0 0"/>
            <geometry>
                <box size="0.8909267229726481 0.7448161818447459 0.6804117718113273" />
            </geometry>
        </collision>
    </link>
</robot>