<robot name = "robot">
    <link name="Cube0">
        <inertial>
            <origin xyz="0.0 0.0 3" rpy="0 0 0"/>
            <mass value="1" />
            <inertia ixx="100" ixy="0" ixz="0" iyy="100" iyz="0" izz="100" />
        </inertial>
        <visual>
            <origin xyz="0.0 0.0 3" rpy="0 0 0"/>
            <geometry>
                <box size="0.2755966989832326 1.4261487098564691 0.7969218791989545" />
            </geometry>
            <material name="Blue">
                <color rgba="0.1 0.2 0.9 0.9"/>
            </material>
        </visual>
        <collision>
            <origin xyz="0.0 0.0 3" rpy="0 0 0"/>
            <geometry>
                <box size="0.2755966989832326 1.4261487098564691 0.7969218791989545" />
            </geometry>
        </collision>
    </link>
    <joint name="Cube0_Cube1" type="prismatic">
       <parent link="Cube0"/>
       <child  link="Cube1"/>
       <origin rpy="0 0 0" xyz="0.0 -0.7130743549282346 3" />
     <axis xyz="0 1 0"/>
       <limit effort="0.0" lower="-3.14159" upper="3.14159" velocity="0.0"/>
    </joint>
    <link name="Cube1">
        <inertial>
            <origin xyz="0.0 -0.703483922737781 0.0" rpy="0 0 0"/>
            <mass value="1" />
            <inertia ixx="100" ixy="0" ixz="0" iyy="100" iyz="0" izz="100" />
        </inertial>
        <visual>
            <origin xyz="0.0 -0.703483922737781 0.0" rpy="0 0 0"/>
            <geometry>
                <box size="0.2590128849418823 1.406967845475562 0.5138442557023681" />
            </geometry>
            <material name="Green">
                <color rgba="0.1 0.9 0.1 0.9"/>
            </material>
        </visual>
        <collision>
            <origin xyz="0.0 -0.703483922737781 0.0" rpy="0 0 0"/>
            <geometry>
                <box size="0.2590128849418823 1.406967845475562 0.5138442557023681" />
            </geometry>
        </collision>
    </link>
    <joint name="Cube1_Cube2" type="prismatic">
       <parent link="Cube1"/>
       <child  link="Cube2"/>
       <origin rpy="0 0 0" xyz="0.0 -0.703483922737781 -0.25692212785118407" />
     <axis xyz="0 1 0"/>
       <limit effort="0.0" lower="-3.14159" upper="3.14159" velocity="0.0"/>
    </joint>
    <link name="Cube2">
        <inertial>
            <origin xyz="0.0 0.0 -0.29046109831262995" rpy="0 0 0"/>
            <mass value="1" />
            <inertia ixx="100" ixy="0" ixz="0" iyy="100" iyz="0" izz="100" />
        </inertial>
        <visual>
            <origin xyz="0.0 0.0 -0.29046109831262995" rpy="0 0 0"/>
            <geometry>
                <box size="0.21324183840988356 0.716985632020426 0.5809221966252599" />
            </geometry>
            <material name="Green">
                <color rgba="0.1 0.9 0.1 0.9"/>
            </material>
        </visual>
        <collision>
            <origin xyz="0.0 0.0 -0.29046109831262995" rpy="0 0 0"/>
            <geometry>
                <box size="0.21324183840988356 0.716985632020426 0.5809221966252599" />
            </geometry>
        </collision>
    </link>
    <joint name="Cube2_Cube3" type="fixed">
       <parent link="Cube2"/>
       <child  link="Cube3"/>
       <origin rpy="0 0 0" xyz="0.0 0.0 -0.5809221966252599" />
     <axis xyz="0 1 0"/>
       <limit effort="0.0" lower="-3.14159" upper="3.14159" velocity="0.0"/>
    </joint>
    <link name="Cube3">
        <inertial>
            <origin xyz="0.0 0.0 -0.2762302253992598" rpy="0 0 0"/>
            <mass value="1" />
            <inertia ixx="100" ixy="0" ixz="0" iyy="100" iyz="0" izz="100" />
        </inertial>
        <visual>
            <origin xyz="0.0 0.0 -0.2762302253992598" rpy="0 0 0"/>
            <geometry>
                <box size="0.21845478051937142 0.4185114926964161 0.5524604507985196" />
            </geometry>
            <material name="Blue">
                <color rgba="0.1 0.2 0.9 0.9"/>
            </material>
        </visual>
        <collision>
            <origin xyz="0.0 0.0 -0.2762302253992598" rpy="0 0 0"/>
            <geometry>
                <box size="0.21845478051937142 0.4185114926964161 0.5524604507985196" />
            </geometry>
        </collision>
    </link>
    <joint name="Cube3_Cube4" type="revolute">
       <parent link="Cube3"/>
       <child  link="Cube4"/>
       <origin rpy="0 0 0" xyz="0.0 -0.20925574634820804 -0.2762302253992598" />
     <axis xyz="0 1 0"/>
       <limit effort="0.0" lower="-3.14159" upper="3.14159" velocity="0.0"/>
    </joint>
    <link name="Cube4">
        <inertial>
            <origin xyz="0.0 -0.5028928185658303 0.0" rpy="0 0 0"/>
            <mass value="1" />
            <inertia ixx="100" ixy="0" ixz="0" iyy="100" iyz="0" izz="100" />
        </inertial>
        <visual>
            <origin xyz="0.0 -0.5028928185658303 0.0" rpy="0 0 0"/>
            <geometry>
                <box size="0.23969804941713796 1.0057856371316607 0.66814938041945" />
            </geometry>
            <material name="Blue">
                <color rgba="0.1 0.2 0.9 0.9"/>
            </material>
        </visual>
        <collision>
            <origin xyz="0.0 -0.5028928185658303 0.0" rpy="0 0 0"/>
            <geometry>
                <box size="0.23969804941713796 1.0057856371316607 0.66814938041945" />
            </geometry>
        </collision>
    </link>
</robot>