<robot name = "robot">
    <link name="Cube0">
        <inertial>
            <origin xyz="0.0 0.0 1.1737275009717258" rpy="0 0 0"/>
            <mass value="1" />
            <inertia ixx="100" ixy="0" ixz="0" iyy="100" iyz="0" izz="100" />
        </inertial>
        <visual>
            <origin xyz="0.0 0.0 1.1737275009717258" rpy="0 0 0"/>
            <geometry>
                <box size="1.4162648333887855 0.5958564672642277 1.1737275009717258" />
            </geometry>
            <material name="Blue">
                <color rgba="0.1 0.2 0.9 0.9"/>
            </material>
        </visual>
        <collision>
            <origin xyz="0.0 0.0 1.1737275009717258" rpy="0 0 0"/>
            <geometry>
                <box size="1.4162648333887855 0.5958564672642277 1.1737275009717258" />
            </geometry>
        </collision>
    </link>
    <joint name="Cube0_Cube1" type="revolute">
       <parent link="Cube0"/>
       <child  link="Cube1"/>
       <origin rpy="0 0 0" xyz="0.7081324166943928 0.0 1.1737275009717258" />
     <axis xyz="0 1 0"/>
       <limit effort="0.0" lower="-3.14159" upper="3.14159" velocity="0.0"/>
    </joint>
    <link name="Cube1">
        <inertial>
            <origin xyz="0.2771279940085841 0.0 0.0" rpy="0 0 0"/>
            <mass value="1" />
            <inertia ixx="100" ixy="0" ixz="0" iyy="100" iyz="0" izz="100" />
        </inertial>
        <visual>
            <origin xyz="0.2771279940085841 0.0 0.0" rpy="0 0 0"/>
            <geometry>
                <box size="0.5542559880171682 1.3719595992065137 0.6151404245278305" />
            </geometry>
            <material name="Blue">
                <color rgba="0.1 0.2 0.9 0.9"/>
            </material>
        </visual>
        <collision>
            <origin xyz="0.2771279940085841 0.0 0.0" rpy="0 0 0"/>
            <geometry>
                <box size="0.5542559880171682 1.3719595992065137 0.6151404245278305" />
            </geometry>
        </collision>
    </link>
    <joint name="Cube1_Cube2" type="revolute">
       <parent link="Cube1"/>
       <child  link="Cube2"/>
       <origin rpy="0 0 0" xyz="0.5542559880171682 0.0 0.0" />
     <axis xyz="0 1 0"/>
       <limit effort="0.0" lower="-3.14159" upper="3.14159" velocity="0.0"/>
    </joint>
    <link name="Cube2">
        <inertial>
            <origin xyz="0.38966454136155504 0.0 0.0" rpy="0 0 0"/>
            <mass value="1" />
            <inertia ixx="100" ixy="0" ixz="0" iyy="100" iyz="0" izz="100" />
        </inertial>
        <visual>
            <origin xyz="0.38966454136155504 0.0 0.0" rpy="0 0 0"/>
            <geometry>
                <box size="0.7793290827231101 1.1862708498460999 1.1684708418728338" />
            </geometry>
            <material name="Green">
                <color rgba="0.1 0.9 0.1 0.9"/>
            </material>
        </visual>
        <collision>
            <origin xyz="0.38966454136155504 0.0 0.0" rpy="0 0 0"/>
            <geometry>
                <box size="0.7793290827231101 1.1862708498460999 1.1684708418728338" />
            </geometry>
        </collision>
    </link>
    <joint name="Cube2_Cube3" type="revolute">
       <parent link="Cube2"/>
       <child  link="Cube3"/>
       <origin rpy="0 0 0" xyz="0.7793290827231101 0.0 0.0" />
     <axis xyz="0 1 0"/>
       <limit effort="0.0" lower="-3.14159" upper="3.14159" velocity="0.0"/>
    </joint>
    <link name="Cube3">
        <inertial>
            <origin xyz="0.35073280132456364 0.0 0.0" rpy="0 0 0"/>
            <mass value="1" />
            <inertia ixx="100" ixy="0" ixz="0" iyy="100" iyz="0" izz="100" />
        </inertial>
        <visual>
            <origin xyz="0.35073280132456364 0.0 0.0" rpy="0 0 0"/>
            <geometry>
                <box size="0.7014656026491273 0.9244912166348469 0.8650249255165048" />
            </geometry>
            <material name="Green">
                <color rgba="0.1 0.9 0.1 0.9"/>
            </material>
        </visual>
        <collision>
            <origin xyz="0.35073280132456364 0.0 0.0" rpy="0 0 0"/>
            <geometry>
                <box size="0.7014656026491273 0.9244912166348469 0.8650249255165048" />
            </geometry>
        </collision>
    </link>
    <joint name="Cube3_Cube4" type="revolute">
       <parent link="Cube3"/>
       <child  link="Cube4"/>
       <origin rpy="0 0 0" xyz="0.7014656026491273 0.0 0.0" />
     <axis xyz="0 1 0"/>
       <limit effort="0.0" lower="-3.14159" upper="3.14159" velocity="0.0"/>
    </joint>
    <link name="Cube4">
        <inertial>
            <origin xyz="0.7338411641841895 0.0 0.0" rpy="0 0 0"/>
            <mass value="1" />
            <inertia ixx="100" ixy="0" ixz="0" iyy="100" iyz="0" izz="100" />
        </inertial>
        <visual>
            <origin xyz="0.7338411641841895 0.0 0.0" rpy="0 0 0"/>
            <geometry>
                <box size="1.467682328368379 0.7020664417060909 0.41955477065732194" />
            </geometry>
            <material name="Blue">
                <color rgba="0.1 0.2 0.9 0.9"/>
            </material>
        </visual>
        <collision>
            <origin xyz="0.7338411641841895 0.0 0.0" rpy="0 0 0"/>
            <geometry>
                <box size="1.467682328368379 0.7020664417060909 0.41955477065732194" />
            </geometry>
        </collision>
    </link>
    <joint name="Cube4_Cube5" type="revolute">
       <parent link="Cube4"/>
       <child  link="Cube5"/>
       <origin rpy="0 0 0" xyz="1.467682328368379 0.0 0.0" />
     <axis xyz="0 1 0"/>
       <limit effort="0.0" lower="-3.14159" upper="3.14159" velocity="0.0"/>
    </joint>
    <link name="Cube5">
        <inertial>
            <origin xyz="0.6126034819155921 0.0 0.0" rpy="0 0 0"/>
            <mass value="1" />
            <inertia ixx="100" ixy="0" ixz="0" iyy="100" iyz="0" izz="100" />
        </inertial>
        <visual>
            <origin xyz="0.6126034819155921 0.0 0.0" rpy="0 0 0"/>
            <geometry>
                <box size="1.2252069638311842 0.6931602885638961 1.419943749625771" />
            </geometry>
            <material name="Green">
                <color rgba="0.1 0.9 0.1 0.9"/>
            </material>
        </visual>
        <collision>
            <origin xyz="0.6126034819155921 0.0 0.0" rpy="0 0 0"/>
            <geometry>
                <box size="1.2252069638311842 0.6931602885638961 1.419943749625771" />
            </geometry>
        </collision>
    </link>
    <joint name="Cube5_Cube6" type="revolute">
       <parent link="Cube5"/>
       <child  link="Cube6"/>
       <origin rpy="0 0 0" xyz="1.2252069638311842 0.0 0.0" />
     <axis xyz="0 1 0"/>
       <limit effort="0.0" lower="-3.14159" upper="3.14159" velocity="0.0"/>
    </joint>
    <link name="Cube6">
        <inertial>
            <origin xyz="0.24184154667231464 0.0 0.0" rpy="0 0 0"/>
            <mass value="1" />
            <inertia ixx="100" ixy="0" ixz="0" iyy="100" iyz="0" izz="100" />
        </inertial>
        <visual>
            <origin xyz="0.24184154667231464 0.0 0.0" rpy="0 0 0"/>
            <geometry>
                <box size="0.4836830933446293 1.2922839138159177 0.8825199189658672" />
            </geometry>
            <material name="Green">
                <color rgba="0.1 0.9 0.1 0.9"/>
            </material>
        </visual>
        <collision>
            <origin xyz="0.24184154667231464 0.0 0.0" rpy="0 0 0"/>
            <geometry>
                <box size="0.4836830933446293 1.2922839138159177 0.8825199189658672" />
            </geometry>
        </collision>
    </link>
    <joint name="Cube6_Cube7" type="revolute">
       <parent link="Cube6"/>
       <child  link="Cube7"/>
       <origin rpy="0 0 0" xyz="0.4836830933446293 0.0 0.0" />
     <axis xyz="0 1 0"/>
       <limit effort="0.0" lower="-3.14159" upper="3.14159" velocity="0.0"/>
    </joint>
    <link name="Cube7">
        <inertial>
            <origin xyz="0.4681916424398289 0.0 0.0" rpy="0 0 0"/>
            <mass value="1" />
            <inertia ixx="100" ixy="0" ixz="0" iyy="100" iyz="0" izz="100" />
        </inertial>
        <visual>
            <origin xyz="0.4681916424398289 0.0 0.0" rpy="0 0 0"/>
            <geometry>
                <box size="0.9363832848796578 0.9917380207871453 0.7497096486046053" />
            </geometry>
            <material name="Blue">
                <color rgba="0.1 0.2 0.9 0.9"/>
            </material>
        </visual>
        <collision>
            <origin xyz="0.4681916424398289 0.0 0.0" rpy="0 0 0"/>
            <geometry>
                <box size="0.9363832848796578 0.9917380207871453 0.7497096486046053" />
            </geometry>
        </collision>
    </link>
    <joint name="Cube7_Cube8" type="revolute">
       <parent link="Cube7"/>
       <child  link="Cube8"/>
       <origin rpy="0 0 0" xyz="0.9363832848796578 0.0 0.0" />
     <axis xyz="0 1 0"/>
       <limit effort="0.0" lower="-3.14159" upper="3.14159" velocity="0.0"/>
    </joint>
    <link name="Cube8">
        <inertial>
            <origin xyz="0.6596394544641606 0.0 0.0" rpy="0 0 0"/>
            <mass value="1" />
            <inertia ixx="100" ixy="0" ixz="0" iyy="100" iyz="0" izz="100" />
        </inertial>
        <visual>
            <origin xyz="0.6596394544641606 0.0 0.0" rpy="0 0 0"/>
            <geometry>
                <box size="1.3192789089283212 0.6996738511611821 0.3557826717563976" />
            </geometry>
            <material name="Green">
                <color rgba="0.1 0.9 0.1 0.9"/>
            </material>
        </visual>
        <collision>
            <origin xyz="0.6596394544641606 0.0 0.0" rpy="0 0 0"/>
            <geometry>
                <box size="1.3192789089283212 0.6996738511611821 0.3557826717563976" />
            </geometry>
        </collision>
    </link>
    <joint name="Cube8_Cube9" type="revolute">
       <parent link="Cube8"/>
       <child  link="Cube9"/>
       <origin rpy="0 0 0" xyz="1.3192789089283212 0.0 0.0" />
     <axis xyz="0 1 0"/>
       <limit effort="0.0" lower="-3.14159" upper="3.14159" velocity="0.0"/>
    </joint>
    <link name="Cube9">
        <inertial>
            <origin xyz="0.4392147418199308 0.0 0.0" rpy="0 0 0"/>
            <mass value="1" />
            <inertia ixx="100" ixy="0" ixz="0" iyy="100" iyz="0" izz="100" />
        </inertial>
        <visual>
            <origin xyz="0.4392147418199308 0.0 0.0" rpy="0 0 0"/>
            <geometry>
                <box size="0.8784294836398616 0.7264944207367168 0.9169304662787383" />
            </geometry>
            <material name="Green">
                <color rgba="0.1 0.9 0.1 0.9"/>
            </material>
        </visual>
        <collision>
            <origin xyz="0.4392147418199308 0.0 0.0" rpy="0 0 0"/>
            <geometry>
                <box size="0.8784294836398616 0.7264944207367168 0.9169304662787383" />
            </geometry>
        </collision>
    </link>
</robot>