<robot name = "robot">
    <link name="Cube0">
        <inertial>
            <origin xyz="0.0 0.0 1.0013301985950374" rpy="0 0 0"/>
            <mass value="1" />
            <inertia ixx="100" ixy="0" ixz="0" iyy="100" iyz="0" izz="100" />
        </inertial>
        <visual>
            <origin xyz="0.0 0.0 1.0013301985950374" rpy="0 0 0"/>
            <geometry>
                <box size="1.3104970524928239 0.8069200459879149 1.0013301985950374" />
            </geometry>
            <material name="Blue">
                <color rgba="0.1 0.2 0.9 0.9"/>
            </material>
        </visual>
        <collision>
            <origin xyz="0.0 0.0 1.0013301985950374" rpy="0 0 0"/>
            <geometry>
                <box size="1.3104970524928239 0.8069200459879149 1.0013301985950374" />
            </geometry>
        </collision>
    </link>
    <joint name="Cube0_Cube1" type="revolute">
       <parent link="Cube0"/>
       <child  link="Cube1"/>
       <origin rpy="0 0 0" xyz="0.32762426312320597 0.0 0.5006650992975187" />
     <axis xyz="0 1 0"/>
       <limit effort="0.0" lower="-3.14159" upper="3.14159" velocity="0.0"/>
    </joint>
    <link name="Cube1">
        <inertial>
            <origin xyz="0.6117092944067619 0.0 0.5006650992975187" rpy="0 0 0"/>
            <mass value="1" />
            <inertia ixx="100" ixy="0" ixz="0" iyy="100" iyz="0" izz="100" />
        </inertial>
        <visual>
            <origin xyz="0.6117092944067619 0.0 0.5006650992975187" rpy="0 0 0"/>
            <geometry>
                <box size="0.5681700625671118 1.688915554915399 1.992641160912341" />
            </geometry>
            <material name="Green">
                <color rgba="0.1 0.9 0.1 1.0"/>
            </material>
        </visual>
        <collision>
            <origin xyz="0.6117092944067619 0.0 0.5006650992975187" rpy="0 0 0"/>
            <geometry>
                <box size="0.5681700625671118 1.688915554915399 1.992641160912341" />
            </geometry>
        </collision>
    </link>
</robot>