<robot name = "robot">
    <link name="Cube0">
        <inertial>
            <origin xyz="0.0 0.0 3" rpy="0 0 0"/>
            <mass value="1" />
            <inertia ixx="100" ixy="0" ixz="0" iyy="100" iyz="0" izz="100" />
        </inertial>
        <visual>
            <origin xyz="0.0 0.0 3" rpy="0 0 0"/>
            <geometry>
                <box size="0.75 0.75 0.75" />
            </geometry>
            <material name="Blue">
                <color rgba="0.1 0.2 0.9 0.9"/>
            </material>
        </visual>
        <collision>
            <origin xyz="0.0 0.0 3" rpy="0 0 0"/>
            <geometry>
                <box size="0.75 0.75 0.75" />
            </geometry>
        </collision>
    </link>
    <joint name="Cube0_Cube1" type="revolute">
       <parent link="Cube0"/>
       <child  link="Cube1"/>
       <origin rpy="0 0 0" xyz="0.0 -0.375 3" />
     <axis xyz="0 1 0"/>
       <limit effort="0.0" lower="-3.14159" upper="3.14159" velocity="0.0"/>
    </joint>
    <link name="Cube1">
        <inertial>
            <origin xyz="0.0 -0.24968422939053325 0.0" rpy="0 0 0"/>
            <mass value="1" />
            <inertia ixx="100" ixy="0" ixz="0" iyy="100" iyz="0" izz="100" />
        </inertial>
        <visual>
            <origin xyz="0.0 -0.24968422939053325 0.0" rpy="0 0 0"/>
            <geometry>
                <box size="0.6423303190634311 0.4993684587810665 0.27928582028762894" />
            </geometry>
            <material name="Blue">
                <color rgba="0.1 0.2 0.9 0.9"/>
            </material>
        </visual>
        <collision>
            <origin xyz="0.0 -0.24968422939053325 0.0" rpy="0 0 0"/>
            <geometry>
                <box size="0.6423303190634311 0.4993684587810665 0.27928582028762894" />
            </geometry>
        </collision>
    </link>
    <joint name="Cube1_Cube2" type="revolute">
       <parent link="Cube1"/>
       <child  link="Cube2"/>
       <origin rpy="0 0 0" xyz="0.0 -0.4993684587810665 0.0" />
     <axis xyz="0 1 0"/>
       <limit effort="0.0" lower="-3.14159" upper="3.14159" velocity="0.0"/>
    </joint>
    <link name="Cube2">
        <inertial>
            <origin xyz="0.0 -0.24968422939053325 0.0" rpy="0 0 0"/>
            <mass value="1" />
            <inertia ixx="100" ixy="0" ixz="0" iyy="100" iyz="0" izz="100" />
        </inertial>
        <visual>
            <origin xyz="0.0 -0.24968422939053325 0.0" rpy="0 0 0"/>
            <geometry>
                <box size="0.6423303190634311 0.4993684587810665 0.27928582028762894" />
            </geometry>
            <material name="Green">
                <color rgba="0.1 0.9 0.1 0.9"/>
            </material>
        </visual>
        <collision>
            <origin xyz="0.0 -0.24968422939053325 0.0" rpy="0 0 0"/>
            <geometry>
                <box size="0.6423303190634311 0.4993684587810665 0.27928582028762894" />
            </geometry>
        </collision>
    </link>
    <joint name="Cube2_Cube3" type="revolute">
       <parent link="Cube2"/>
       <child  link="Cube3"/>
       <origin rpy="0 0 0" xyz="0.0 -0.24968422939053325 -0.13964291014381447" />
     <axis xyz="0 1 0"/>
       <limit effort="0.0" lower="-3.14159" upper="3.14159" velocity="0.0"/>
    </joint>
    <link name="Cube3">
        <inertial>
            <origin xyz="0.0 0.0 -0.13964291014381447" rpy="0 0 0"/>
            <mass value="1" />
            <inertia ixx="100" ixy="0" ixz="0" iyy="100" iyz="0" izz="100" />
        </inertial>
        <visual>
            <origin xyz="0.0 0.0 -0.13964291014381447" rpy="0 0 0"/>
            <geometry>
                <box size="0.6423303190634311 0.4993684587810665 0.27928582028762894" />
            </geometry>
            <material name="Blue">
                <color rgba="0.1 0.2 0.9 0.9"/>
            </material>
        </visual>
        <collision>
            <origin xyz="0.0 0.0 -0.13964291014381447" rpy="0 0 0"/>
            <geometry>
                <box size="0.6423303190634311 0.4993684587810665 0.27928582028762894" />
            </geometry>
        </collision>
    </link>
    <joint name="Cube3_Cube4" type="revolute">
       <parent link="Cube3"/>
       <child  link="Cube4"/>
       <origin rpy="0 0 0" xyz="0.0 -0.24968422939053325 -0.13964291014381447" />
     <axis xyz="0 1 0"/>
       <limit effort="0.0" lower="-3.14159" upper="3.14159" velocity="0.0"/>
    </joint>
    <link name="Cube4">
        <inertial>
            <origin xyz="0.0 -0.24968422939053325 0.0" rpy="0 0 0"/>
            <mass value="1" />
            <inertia ixx="100" ixy="0" ixz="0" iyy="100" iyz="0" izz="100" />
        </inertial>
        <visual>
            <origin xyz="0.0 -0.24968422939053325 0.0" rpy="0 0 0"/>
            <geometry>
                <box size="0.6423303190634311 0.4993684587810665 0.27928582028762894" />
            </geometry>
            <material name="Green">
                <color rgba="0.1 0.9 0.1 0.9"/>
            </material>
        </visual>
        <collision>
            <origin xyz="0.0 -0.24968422939053325 0.0" rpy="0 0 0"/>
            <geometry>
                <box size="0.6423303190634311 0.4993684587810665 0.27928582028762894" />
            </geometry>
        </collision>
    </link>
    <joint name="Cube4_Cube5" type="revolute">
       <parent link="Cube4"/>
       <child  link="Cube5"/>
       <origin rpy="0 0 0" xyz="0.0 -0.4993684587810665 0.0" />
     <axis xyz="0 1 0"/>
       <limit effort="0.0" lower="-3.14159" upper="3.14159" velocity="0.0"/>
    </joint>
    <link name="Cube5">
        <inertial>
            <origin xyz="0.0 -0.24968422939053325 0.0" rpy="0 0 0"/>
            <mass value="1" />
            <inertia ixx="100" ixy="0" ixz="0" iyy="100" iyz="0" izz="100" />
        </inertial>
        <visual>
            <origin xyz="0.0 -0.24968422939053325 0.0" rpy="0 0 0"/>
            <geometry>
                <box size="0.6423303190634311 0.4993684587810665 0.27928582028762894" />
            </geometry>
            <material name="Green">
                <color rgba="0.1 0.9 0.1 0.9"/>
            </material>
        </visual>
        <collision>
            <origin xyz="0.0 -0.24968422939053325 0.0" rpy="0 0 0"/>
            <geometry>
                <box size="0.6423303190634311 0.4993684587810665 0.27928582028762894" />
            </geometry>
        </collision>
    </link>
    <joint name="Cube0_Cube6" type="revolute">
       <parent link="Cube0"/>
       <child  link="Cube6"/>
       <origin rpy="0 0 0" xyz="0.0 0.375 3" />
     <axis xyz="0 1 0"/>
       <limit effort="0.0" lower="-3.14159" upper="3.14159" velocity="0.0"/>
    </joint>
    <link name="Cube6">
        <inertial>
            <origin xyz="0.0 0.24968422939053325 0.0" rpy="0 0 0"/>
            <mass value="1" />
            <inertia ixx="100" ixy="0" ixz="0" iyy="100" iyz="0" izz="100" />
        </inertial>
        <visual>
            <origin xyz="0.0 0.24968422939053325 0.0" rpy="0 0 0"/>
            <geometry>
                <box size="0.6423303190634311 0.4993684587810665 0.27928582028762894" />
            </geometry>
            <material name="Green">
                <color rgba="0.1 0.9 0.1 0.9"/>
            </material>
        </visual>
        <collision>
            <origin xyz="0.0 0.24968422939053325 0.0" rpy="0 0 0"/>
            <geometry>
                <box size="0.6423303190634311 0.4993684587810665 0.27928582028762894" />
            </geometry>
        </collision>
    </link>
    <joint name="Cube6_Cube7" type="revolute">
       <parent link="Cube6"/>
       <child  link="Cube7"/>
       <origin rpy="0 0 0" xyz="0.0 0.4993684587810665 0.0" />
     <axis xyz="0 1 0"/>
       <limit effort="0.0" lower="-3.14159" upper="3.14159" velocity="0.0"/>
    </joint>
    <link name="Cube7">
        <inertial>
            <origin xyz="0.0 0.24968422939053325 0.0" rpy="0 0 0"/>
            <mass value="1" />
            <inertia ixx="100" ixy="0" ixz="0" iyy="100" iyz="0" izz="100" />
        </inertial>
        <visual>
            <origin xyz="0.0 0.24968422939053325 0.0" rpy="0 0 0"/>
            <geometry>
                <box size="0.6423303190634311 0.4993684587810665 0.27928582028762894" />
            </geometry>
            <material name="Green">
                <color rgba="0.1 0.9 0.1 0.9"/>
            </material>
        </visual>
        <collision>
            <origin xyz="0.0 0.24968422939053325 0.0" rpy="0 0 0"/>
            <geometry>
                <box size="0.6423303190634311 0.4993684587810665 0.27928582028762894" />
            </geometry>
        </collision>
    </link>
    <joint name="Cube7_Cube8" type="revolute">
       <parent link="Cube7"/>
       <child  link="Cube8"/>
       <origin rpy="0 0 0" xyz="0.0 0.24968422939053325 -0.13964291014381447" />
     <axis xyz="0 1 0"/>
       <limit effort="0.0" lower="-3.14159" upper="3.14159" velocity="0.0"/>
    </joint>
    <link name="Cube8">
        <inertial>
            <origin xyz="0.0 0.0 -0.13964291014381447" rpy="0 0 0"/>
            <mass value="1" />
            <inertia ixx="100" ixy="0" ixz="0" iyy="100" iyz="0" izz="100" />
        </inertial>
        <visual>
            <origin xyz="0.0 0.0 -0.13964291014381447" rpy="0 0 0"/>
            <geometry>
                <box size="0.6423303190634311 0.4993684587810665 0.27928582028762894" />
            </geometry>
            <material name="Green">
                <color rgba="0.1 0.9 0.1 0.9"/>
            </material>
        </visual>
        <collision>
            <origin xyz="0.0 0.0 -0.13964291014381447" rpy="0 0 0"/>
            <geometry>
                <box size="0.6423303190634311 0.4993684587810665 0.27928582028762894" />
            </geometry>
        </collision>
    </link>
    <joint name="Cube8_Cube9" type="revolute">
       <parent link="Cube8"/>
       <child  link="Cube9"/>
       <origin rpy="0 0 0" xyz="0.0 0.24968422939053325 -0.13964291014381447" />
     <axis xyz="0 1 0"/>
       <limit effort="0.0" lower="-3.14159" upper="3.14159" velocity="0.0"/>
    </joint>
    <link name="Cube9">
        <inertial>
            <origin xyz="0.0 0.24968422939053325 0.0" rpy="0 0 0"/>
            <mass value="1" />
            <inertia ixx="100" ixy="0" ixz="0" iyy="100" iyz="0" izz="100" />
        </inertial>
        <visual>
            <origin xyz="0.0 0.24968422939053325 0.0" rpy="0 0 0"/>
            <geometry>
                <box size="0.6423303190634311 0.4993684587810665 0.27928582028762894" />
            </geometry>
            <material name="Blue">
                <color rgba="0.1 0.2 0.9 0.9"/>
            </material>
        </visual>
        <collision>
            <origin xyz="0.0 0.24968422939053325 0.0" rpy="0 0 0"/>
            <geometry>
                <box size="0.6423303190634311 0.4993684587810665 0.27928582028762894" />
            </geometry>
        </collision>
    </link>
    <joint name="Cube9_Cube10" type="revolute">
       <parent link="Cube9"/>
       <child  link="Cube10"/>
       <origin rpy="0 0 0" xyz="0.0 0.4993684587810665 0.0" />
     <axis xyz="0 1 0"/>
       <limit effort="0.0" lower="-3.14159" upper="3.14159" velocity="0.0"/>
    </joint>
    <link name="Cube10">
        <inertial>
            <origin xyz="0.0 0.24968422939053325 0.0" rpy="0 0 0"/>
            <mass value="1" />
            <inertia ixx="100" ixy="0" ixz="0" iyy="100" iyz="0" izz="100" />
        </inertial>
        <visual>
            <origin xyz="0.0 0.24968422939053325 0.0" rpy="0 0 0"/>
            <geometry>
                <box size="0.6423303190634311 0.4993684587810665 0.27928582028762894" />
            </geometry>
            <material name="Green">
                <color rgba="0.1 0.9 0.1 0.9"/>
            </material>
        </visual>
        <collision>
            <origin xyz="0.0 0.24968422939053325 0.0" rpy="0 0 0"/>
            <geometry>
                <box size="0.6423303190634311 0.4993684587810665 0.27928582028762894" />
            </geometry>
        </collision>
    </link>
    <joint name="Cube0_Cube11" type="revolute">
       <parent link="Cube0"/>
       <child  link="Cube11"/>
       <origin rpy="0 0 0" xyz="0.375 0.0 3" />
     <axis xyz="0 1 0"/>
       <limit effort="0.0" lower="-3.14159" upper="3.14159" velocity="0.0"/>
    </joint>
    <link name="Cube11">
        <inertial>
            <origin xyz="0.375 0.0 0.0" rpy="0 0 0"/>
            <mass value="1" />
            <inertia ixx="100" ixy="0" ixz="0" iyy="100" iyz="0" izz="100" />
        </inertial>
        <visual>
            <origin xyz="0.375 0.0 0.0" rpy="0 0 0"/>
            <geometry>
                <box size="0.75 0.75 0.75" />
            </geometry>
            <material name="Green">
                <color rgba="0.1 0.9 0.1 0.9"/>
            </material>
        </visual>
        <collision>
            <origin xyz="0.375 0.0 0.0" rpy="0 0 0"/>
            <geometry>
                <box size="0.75 0.75 0.75" />
            </geometry>
        </collision>
    </link>
    <joint name="Cube11_Cube12" type="revolute">
       <parent link="Cube11"/>
       <child  link="Cube12"/>
       <origin rpy="0 0 0" xyz="0.375 -0.375 0.0" />
     <axis xyz="0 1 0"/>
       <limit effort="0.0" lower="-3.14159" upper="3.14159" velocity="0.0"/>
    </joint>
    <link name="Cube12">
        <inertial>
            <origin xyz="0.0 -0.24968422939053325 0.0" rpy="0 0 0"/>
            <mass value="1" />
            <inertia ixx="100" ixy="0" ixz="0" iyy="100" iyz="0" izz="100" />
        </inertial>
        <visual>
            <origin xyz="0.0 -0.24968422939053325 0.0" rpy="0 0 0"/>
            <geometry>
                <box size="0.6423303190634311 0.4993684587810665 0.27928582028762894" />
            </geometry>
            <material name="Green">
                <color rgba="0.1 0.9 0.1 0.9"/>
            </material>
        </visual>
        <collision>
            <origin xyz="0.0 -0.24968422939053325 0.0" rpy="0 0 0"/>
            <geometry>
                <box size="0.6423303190634311 0.4993684587810665 0.27928582028762894" />
            </geometry>
        </collision>
    </link>
    <joint name="Cube12_Cube13" type="revolute">
       <parent link="Cube12"/>
       <child  link="Cube13"/>
       <origin rpy="0 0 0" xyz="0.0 -0.4993684587810665 0.0" />
     <axis xyz="0 1 0"/>
       <limit effort="0.0" lower="-3.14159" upper="3.14159" velocity="0.0"/>
    </joint>
    <link name="Cube13">
        <inertial>
            <origin xyz="0.0 -0.24968422939053325 0.0" rpy="0 0 0"/>
            <mass value="1" />
            <inertia ixx="100" ixy="0" ixz="0" iyy="100" iyz="0" izz="100" />
        </inertial>
        <visual>
            <origin xyz="0.0 -0.24968422939053325 0.0" rpy="0 0 0"/>
            <geometry>
                <box size="0.6423303190634311 0.4993684587810665 0.27928582028762894" />
            </geometry>
            <material name="Blue">
                <color rgba="0.1 0.2 0.9 0.9"/>
            </material>
        </visual>
        <collision>
            <origin xyz="0.0 -0.24968422939053325 0.0" rpy="0 0 0"/>
            <geometry>
                <box size="0.6423303190634311 0.4993684587810665 0.27928582028762894" />
            </geometry>
        </collision>
    </link>
    <joint name="Cube13_Cube14" type="revolute">
       <parent link="Cube13"/>
       <child  link="Cube14"/>
       <origin rpy="0 0 0" xyz="0.0 -0.24968422939053325 -0.13964291014381447" />
     <axis xyz="0 1 0"/>
       <limit effort="0.0" lower="-3.14159" upper="3.14159" velocity="0.0"/>
    </joint>
    <link name="Cube14">
        <inertial>
            <origin xyz="0.0 0.0 -0.13964291014381447" rpy="0 0 0"/>
            <mass value="1" />
            <inertia ixx="100" ixy="0" ixz="0" iyy="100" iyz="0" izz="100" />
        </inertial>
        <visual>
            <origin xyz="0.0 0.0 -0.13964291014381447" rpy="0 0 0"/>
            <geometry>
                <box size="0.6423303190634311 0.4993684587810665 0.27928582028762894" />
            </geometry>
            <material name="Green">
                <color rgba="0.1 0.9 0.1 0.9"/>
            </material>
        </visual>
        <collision>
            <origin xyz="0.0 0.0 -0.13964291014381447" rpy="0 0 0"/>
            <geometry>
                <box size="0.6423303190634311 0.4993684587810665 0.27928582028762894" />
            </geometry>
        </collision>
    </link>
    <joint name="Cube14_Cube15" type="revolute">
       <parent link="Cube14"/>
       <child  link="Cube15"/>
       <origin rpy="0 0 0" xyz="0.0 -0.24968422939053325 -0.13964291014381447" />
     <axis xyz="0 1 0"/>
       <limit effort="0.0" lower="-3.14159" upper="3.14159" velocity="0.0"/>
    </joint>
    <link name="Cube15">
        <inertial>
            <origin xyz="0.0 -0.24968422939053325 0.0" rpy="0 0 0"/>
            <mass value="1" />
            <inertia ixx="100" ixy="0" ixz="0" iyy="100" iyz="0" izz="100" />
        </inertial>
        <visual>
            <origin xyz="0.0 -0.24968422939053325 0.0" rpy="0 0 0"/>
            <geometry>
                <box size="0.6423303190634311 0.4993684587810665 0.27928582028762894" />
            </geometry>
            <material name="Blue">
                <color rgba="0.1 0.2 0.9 0.9"/>
            </material>
        </visual>
        <collision>
            <origin xyz="0.0 -0.24968422939053325 0.0" rpy="0 0 0"/>
            <geometry>
                <box size="0.6423303190634311 0.4993684587810665 0.27928582028762894" />
            </geometry>
        </collision>
    </link>
    <joint name="Cube15_Cube16" type="revolute">
       <parent link="Cube15"/>
       <child  link="Cube16"/>
       <origin rpy="0 0 0" xyz="0.0 -0.4993684587810665 0.0" />
     <axis xyz="0 1 0"/>
       <limit effort="0.0" lower="-3.14159" upper="3.14159" velocity="0.0"/>
    </joint>
    <link name="Cube16">
        <inertial>
            <origin xyz="0.0 -0.24968422939053325 0.0" rpy="0 0 0"/>
            <mass value="1" />
            <inertia ixx="100" ixy="0" ixz="0" iyy="100" iyz="0" izz="100" />
        </inertial>
        <visual>
            <origin xyz="0.0 -0.24968422939053325 0.0" rpy="0 0 0"/>
            <geometry>
                <box size="0.6423303190634311 0.4993684587810665 0.27928582028762894" />
            </geometry>
            <material name="Green">
                <color rgba="0.1 0.9 0.1 0.9"/>
            </material>
        </visual>
        <collision>
            <origin xyz="0.0 -0.24968422939053325 0.0" rpy="0 0 0"/>
            <geometry>
                <box size="0.6423303190634311 0.4993684587810665 0.27928582028762894" />
            </geometry>
        </collision>
    </link>
    <joint name="Cube11_Cube17" type="revolute">
       <parent link="Cube11"/>
       <child  link="Cube17"/>
       <origin rpy="0 0 0" xyz="0.375 0.375 0.0" />
     <axis xyz="0 1 0"/>
       <limit effort="0.0" lower="-3.14159" upper="3.14159" velocity="0.0"/>
    </joint>
    <link name="Cube17">
        <inertial>
            <origin xyz="0.0 0.24968422939053325 0.0" rpy="0 0 0"/>
            <mass value="1" />
            <inertia ixx="100" ixy="0" ixz="0" iyy="100" iyz="0" izz="100" />
        </inertial>
        <visual>
            <origin xyz="0.0 0.24968422939053325 0.0" rpy="0 0 0"/>
            <geometry>
                <box size="0.6423303190634311 0.4993684587810665 0.27928582028762894" />
            </geometry>
            <material name="Blue">
                <color rgba="0.1 0.2 0.9 0.9"/>
            </material>
        </visual>
        <collision>
            <origin xyz="0.0 0.24968422939053325 0.0" rpy="0 0 0"/>
            <geometry>
                <box size="0.6423303190634311 0.4993684587810665 0.27928582028762894" />
            </geometry>
        </collision>
    </link>
    <joint name="Cube17_Cube18" type="revolute">
       <parent link="Cube17"/>
       <child  link="Cube18"/>
       <origin rpy="0 0 0" xyz="0.0 0.4993684587810665 0.0" />
     <axis xyz="0 1 0"/>
       <limit effort="0.0" lower="-3.14159" upper="3.14159" velocity="0.0"/>
    </joint>
    <link name="Cube18">
        <inertial>
            <origin xyz="0.0 0.24968422939053325 0.0" rpy="0 0 0"/>
            <mass value="1" />
            <inertia ixx="100" ixy="0" ixz="0" iyy="100" iyz="0" izz="100" />
        </inertial>
        <visual>
            <origin xyz="0.0 0.24968422939053325 0.0" rpy="0 0 0"/>
            <geometry>
                <box size="0.6423303190634311 0.4993684587810665 0.27928582028762894" />
            </geometry>
            <material name="Green">
                <color rgba="0.1 0.9 0.1 0.9"/>
            </material>
        </visual>
        <collision>
            <origin xyz="0.0 0.24968422939053325 0.0" rpy="0 0 0"/>
            <geometry>
                <box size="0.6423303190634311 0.4993684587810665 0.27928582028762894" />
            </geometry>
        </collision>
    </link>
    <joint name="Cube18_Cube19" type="revolute">
       <parent link="Cube18"/>
       <child  link="Cube19"/>
       <origin rpy="0 0 0" xyz="0.0 0.24968422939053325 -0.13964291014381447" />
     <axis xyz="0 1 0"/>
       <limit effort="0.0" lower="-3.14159" upper="3.14159" velocity="0.0"/>
    </joint>
    <link name="Cube19">
        <inertial>
            <origin xyz="0.0 0.0 -0.13964291014381447" rpy="0 0 0"/>
            <mass value="1" />
            <inertia ixx="100" ixy="0" ixz="0" iyy="100" iyz="0" izz="100" />
        </inertial>
        <visual>
            <origin xyz="0.0 0.0 -0.13964291014381447" rpy="0 0 0"/>
            <geometry>
                <box size="0.6423303190634311 0.4993684587810665 0.27928582028762894" />
            </geometry>
            <material name="Green">
                <color rgba="0.1 0.9 0.1 0.9"/>
            </material>
        </visual>
        <collision>
            <origin xyz="0.0 0.0 -0.13964291014381447" rpy="0 0 0"/>
            <geometry>
                <box size="0.6423303190634311 0.4993684587810665 0.27928582028762894" />
            </geometry>
        </collision>
    </link>
    <joint name="Cube19_Cube20" type="revolute">
       <parent link="Cube19"/>
       <child  link="Cube20"/>
       <origin rpy="0 0 0" xyz="0.0 0.24968422939053325 -0.13964291014381447" />
     <axis xyz="0 1 0"/>
       <limit effort="0.0" lower="-3.14159" upper="3.14159" velocity="0.0"/>
    </joint>
    <link name="Cube20">
        <inertial>
            <origin xyz="0.0 0.24968422939053325 0.0" rpy="0 0 0"/>
            <mass value="1" />
            <inertia ixx="100" ixy="0" ixz="0" iyy="100" iyz="0" izz="100" />
        </inertial>
        <visual>
            <origin xyz="0.0 0.24968422939053325 0.0" rpy="0 0 0"/>
            <geometry>
                <box size="0.6423303190634311 0.4993684587810665 0.27928582028762894" />
            </geometry>
            <material name="Green">
                <color rgba="0.1 0.9 0.1 0.9"/>
            </material>
        </visual>
        <collision>
            <origin xyz="0.0 0.24968422939053325 0.0" rpy="0 0 0"/>
            <geometry>
                <box size="0.6423303190634311 0.4993684587810665 0.27928582028762894" />
            </geometry>
        </collision>
    </link>
    <joint name="Cube20_Cube21" type="revolute">
       <parent link="Cube20"/>
       <child  link="Cube21"/>
       <origin rpy="0 0 0" xyz="0.0 0.4993684587810665 0.0" />
     <axis xyz="0 1 0"/>
       <limit effort="0.0" lower="-3.14159" upper="3.14159" velocity="0.0"/>
    </joint>
    <link name="Cube21">
        <inertial>
            <origin xyz="0.0 0.24968422939053325 0.0" rpy="0 0 0"/>
            <mass value="1" />
            <inertia ixx="100" ixy="0" ixz="0" iyy="100" iyz="0" izz="100" />
        </inertial>
        <visual>
            <origin xyz="0.0 0.24968422939053325 0.0" rpy="0 0 0"/>
            <geometry>
                <box size="0.6423303190634311 0.4993684587810665 0.27928582028762894" />
            </geometry>
            <material name="Green">
                <color rgba="0.1 0.9 0.1 0.9"/>
            </material>
        </visual>
        <collision>
            <origin xyz="0.0 0.24968422939053325 0.0" rpy="0 0 0"/>
            <geometry>
                <box size="0.6423303190634311 0.4993684587810665 0.27928582028762894" />
            </geometry>
        </collision>
    </link>
    <joint name="Cube11_Cube22" type="revolute">
       <parent link="Cube11"/>
       <child  link="Cube22"/>
       <origin rpy="0 0 0" xyz="0.75 0.0 0.0" />
     <axis xyz="0 1 0"/>
       <limit effort="0.0" lower="-3.14159" upper="3.14159" velocity="0.0"/>
    </joint>
    <link name="Cube22">
        <inertial>
            <origin xyz="0.375 0.0 0.0" rpy="0 0 0"/>
            <mass value="1" />
            <inertia ixx="100" ixy="0" ixz="0" iyy="100" iyz="0" izz="100" />
        </inertial>
        <visual>
            <origin xyz="0.375 0.0 0.0" rpy="0 0 0"/>
            <geometry>
                <box size="0.75 0.75 0.75" />
            </geometry>
            <material name="Blue">
                <color rgba="0.1 0.2 0.9 0.9"/>
            </material>
        </visual>
        <collision>
            <origin xyz="0.375 0.0 0.0" rpy="0 0 0"/>
            <geometry>
                <box size="0.75 0.75 0.75" />
            </geometry>
        </collision>
    </link>
    <joint name="Cube22_Cube23" type="revolute">
       <parent link="Cube22"/>
       <child  link="Cube23"/>
       <origin rpy="0 0 0" xyz="0.375 -0.375 0.0" />
     <axis xyz="0 1 0"/>
       <limit effort="0.0" lower="-3.14159" upper="3.14159" velocity="0.0"/>
    </joint>
    <link name="Cube23">
        <inertial>
            <origin xyz="0.0 -0.24968422939053325 0.0" rpy="0 0 0"/>
            <mass value="1" />
            <inertia ixx="100" ixy="0" ixz="0" iyy="100" iyz="0" izz="100" />
        </inertial>
        <visual>
            <origin xyz="0.0 -0.24968422939053325 0.0" rpy="0 0 0"/>
            <geometry>
                <box size="0.6423303190634311 0.4993684587810665 0.27928582028762894" />
            </geometry>
            <material name="Blue">
                <color rgba="0.1 0.2 0.9 0.9"/>
            </material>
        </visual>
        <collision>
            <origin xyz="0.0 -0.24968422939053325 0.0" rpy="0 0 0"/>
            <geometry>
                <box size="0.6423303190634311 0.4993684587810665 0.27928582028762894" />
            </geometry>
        </collision>
    </link>
    <joint name="Cube23_Cube24" type="revolute">
       <parent link="Cube23"/>
       <child  link="Cube24"/>
       <origin rpy="0 0 0" xyz="0.0 -0.4993684587810665 0.0" />
     <axis xyz="0 1 0"/>
       <limit effort="0.0" lower="-3.14159" upper="3.14159" velocity="0.0"/>
    </joint>
    <link name="Cube24">
        <inertial>
            <origin xyz="0.0 -0.24968422939053325 0.0" rpy="0 0 0"/>
            <mass value="1" />
            <inertia ixx="100" ixy="0" ixz="0" iyy="100" iyz="0" izz="100" />
        </inertial>
        <visual>
            <origin xyz="0.0 -0.24968422939053325 0.0" rpy="0 0 0"/>
            <geometry>
                <box size="0.6423303190634311 0.4993684587810665 0.27928582028762894" />
            </geometry>
            <material name="Blue">
                <color rgba="0.1 0.2 0.9 0.9"/>
            </material>
        </visual>
        <collision>
            <origin xyz="0.0 -0.24968422939053325 0.0" rpy="0 0 0"/>
            <geometry>
                <box size="0.6423303190634311 0.4993684587810665 0.27928582028762894" />
            </geometry>
        </collision>
    </link>
    <joint name="Cube24_Cube25" type="revolute">
       <parent link="Cube24"/>
       <child  link="Cube25"/>
       <origin rpy="0 0 0" xyz="0.0 -0.24968422939053325 -0.13964291014381447" />
     <axis xyz="0 1 0"/>
       <limit effort="0.0" lower="-3.14159" upper="3.14159" velocity="0.0"/>
    </joint>
    <link name="Cube25">
        <inertial>
            <origin xyz="0.0 0.0 -0.13964291014381447" rpy="0 0 0"/>
            <mass value="1" />
            <inertia ixx="100" ixy="0" ixz="0" iyy="100" iyz="0" izz="100" />
        </inertial>
        <visual>
            <origin xyz="0.0 0.0 -0.13964291014381447" rpy="0 0 0"/>
            <geometry>
                <box size="0.6423303190634311 0.4993684587810665 0.27928582028762894" />
            </geometry>
            <material name="Green">
                <color rgba="0.1 0.9 0.1 0.9"/>
            </material>
        </visual>
        <collision>
            <origin xyz="0.0 0.0 -0.13964291014381447" rpy="0 0 0"/>
            <geometry>
                <box size="0.6423303190634311 0.4993684587810665 0.27928582028762894" />
            </geometry>
        </collision>
    </link>
    <joint name="Cube25_Cube26" type="revolute">
       <parent link="Cube25"/>
       <child  link="Cube26"/>
       <origin rpy="0 0 0" xyz="0.0 -0.24968422939053325 -0.13964291014381447" />
     <axis xyz="0 1 0"/>
       <limit effort="0.0" lower="-3.14159" upper="3.14159" velocity="0.0"/>
    </joint>
    <link name="Cube26">
        <inertial>
            <origin xyz="0.0 -0.24968422939053325 0.0" rpy="0 0 0"/>
            <mass value="1" />
            <inertia ixx="100" ixy="0" ixz="0" iyy="100" iyz="0" izz="100" />
        </inertial>
        <visual>
            <origin xyz="0.0 -0.24968422939053325 0.0" rpy="0 0 0"/>
            <geometry>
                <box size="0.6423303190634311 0.4993684587810665 0.27928582028762894" />
            </geometry>
            <material name="Blue">
                <color rgba="0.1 0.2 0.9 0.9"/>
            </material>
        </visual>
        <collision>
            <origin xyz="0.0 -0.24968422939053325 0.0" rpy="0 0 0"/>
            <geometry>
                <box size="0.6423303190634311 0.4993684587810665 0.27928582028762894" />
            </geometry>
        </collision>
    </link>
    <joint name="Cube26_Cube27" type="revolute">
       <parent link="Cube26"/>
       <child  link="Cube27"/>
       <origin rpy="0 0 0" xyz="0.0 -0.4993684587810665 0.0" />
     <axis xyz="0 1 0"/>
       <limit effort="0.0" lower="-3.14159" upper="3.14159" velocity="0.0"/>
    </joint>
    <link name="Cube27">
        <inertial>
            <origin xyz="0.0 -0.24968422939053325 0.0" rpy="0 0 0"/>
            <mass value="1" />
            <inertia ixx="100" ixy="0" ixz="0" iyy="100" iyz="0" izz="100" />
        </inertial>
        <visual>
            <origin xyz="0.0 -0.24968422939053325 0.0" rpy="0 0 0"/>
            <geometry>
                <box size="0.6423303190634311 0.4993684587810665 0.27928582028762894" />
            </geometry>
            <material name="Green">
                <color rgba="0.1 0.9 0.1 0.9"/>
            </material>
        </visual>
        <collision>
            <origin xyz="0.0 -0.24968422939053325 0.0" rpy="0 0 0"/>
            <geometry>
                <box size="0.6423303190634311 0.4993684587810665 0.27928582028762894" />
            </geometry>
        </collision>
    </link>
    <joint name="Cube22_Cube28" type="revolute">
       <parent link="Cube22"/>
       <child  link="Cube28"/>
       <origin rpy="0 0 0" xyz="0.375 0.375 0.0" />
     <axis xyz="0 1 0"/>
       <limit effort="0.0" lower="-3.14159" upper="3.14159" velocity="0.0"/>
    </joint>
    <link name="Cube28">
        <inertial>
            <origin xyz="0.0 0.24968422939053325 0.0" rpy="0 0 0"/>
            <mass value="1" />
            <inertia ixx="100" ixy="0" ixz="0" iyy="100" iyz="0" izz="100" />
        </inertial>
        <visual>
            <origin xyz="0.0 0.24968422939053325 0.0" rpy="0 0 0"/>
            <geometry>
                <box size="0.6423303190634311 0.4993684587810665 0.27928582028762894" />
            </geometry>
            <material name="Blue">
                <color rgba="0.1 0.2 0.9 0.9"/>
            </material>
        </visual>
        <collision>
            <origin xyz="0.0 0.24968422939053325 0.0" rpy="0 0 0"/>
            <geometry>
                <box size="0.6423303190634311 0.4993684587810665 0.27928582028762894" />
            </geometry>
        </collision>
    </link>
    <joint name="Cube28_Cube29" type="revolute">
       <parent link="Cube28"/>
       <child  link="Cube29"/>
       <origin rpy="0 0 0" xyz="0.0 0.4993684587810665 0.0" />
     <axis xyz="0 1 0"/>
       <limit effort="0.0" lower="-3.14159" upper="3.14159" velocity="0.0"/>
    </joint>
    <link name="Cube29">
        <inertial>
            <origin xyz="0.0 0.24968422939053325 0.0" rpy="0 0 0"/>
            <mass value="1" />
            <inertia ixx="100" ixy="0" ixz="0" iyy="100" iyz="0" izz="100" />
        </inertial>
        <visual>
            <origin xyz="0.0 0.24968422939053325 0.0" rpy="0 0 0"/>
            <geometry>
                <box size="0.6423303190634311 0.4993684587810665 0.27928582028762894" />
            </geometry>
            <material name="Blue">
                <color rgba="0.1 0.2 0.9 0.9"/>
            </material>
        </visual>
        <collision>
            <origin xyz="0.0 0.24968422939053325 0.0" rpy="0 0 0"/>
            <geometry>
                <box size="0.6423303190634311 0.4993684587810665 0.27928582028762894" />
            </geometry>
        </collision>
    </link>
    <joint name="Cube29_Cube30" type="revolute">
       <parent link="Cube29"/>
       <child  link="Cube30"/>
       <origin rpy="0 0 0" xyz="0.0 0.24968422939053325 -0.13964291014381447" />
     <axis xyz="0 1 0"/>
       <limit effort="0.0" lower="-3.14159" upper="3.14159" velocity="0.0"/>
    </joint>
    <link name="Cube30">
        <inertial>
            <origin xyz="0.0 0.0 -0.13964291014381447" rpy="0 0 0"/>
            <mass value="1" />
            <inertia ixx="100" ixy="0" ixz="0" iyy="100" iyz="0" izz="100" />
        </inertial>
        <visual>
            <origin xyz="0.0 0.0 -0.13964291014381447" rpy="0 0 0"/>
            <geometry>
                <box size="0.6423303190634311 0.4993684587810665 0.27928582028762894" />
            </geometry>
            <material name="Green">
                <color rgba="0.1 0.9 0.1 0.9"/>
            </material>
        </visual>
        <collision>
            <origin xyz="0.0 0.0 -0.13964291014381447" rpy="0 0 0"/>
            <geometry>
                <box size="0.6423303190634311 0.4993684587810665 0.27928582028762894" />
            </geometry>
        </collision>
    </link>
    <joint name="Cube30_Cube31" type="revolute">
       <parent link="Cube30"/>
       <child  link="Cube31"/>
       <origin rpy="0 0 0" xyz="0.0 0.24968422939053325 -0.13964291014381447" />
     <axis xyz="0 1 0"/>
       <limit effort="0.0" lower="-3.14159" upper="3.14159" velocity="0.0"/>
    </joint>
    <link name="Cube31">
        <inertial>
            <origin xyz="0.0 0.24968422939053325 0.0" rpy="0 0 0"/>
            <mass value="1" />
            <inertia ixx="100" ixy="0" ixz="0" iyy="100" iyz="0" izz="100" />
        </inertial>
        <visual>
            <origin xyz="0.0 0.24968422939053325 0.0" rpy="0 0 0"/>
            <geometry>
                <box size="0.6423303190634311 0.4993684587810665 0.27928582028762894" />
            </geometry>
            <material name="Blue">
                <color rgba="0.1 0.2 0.9 0.9"/>
            </material>
        </visual>
        <collision>
            <origin xyz="0.0 0.24968422939053325 0.0" rpy="0 0 0"/>
            <geometry>
                <box size="0.6423303190634311 0.4993684587810665 0.27928582028762894" />
            </geometry>
        </collision>
    </link>
    <joint name="Cube31_Cube32" type="revolute">
       <parent link="Cube31"/>
       <child  link="Cube32"/>
       <origin rpy="0 0 0" xyz="0.0 0.4993684587810665 0.0" />
     <axis xyz="0 1 0"/>
       <limit effort="0.0" lower="-3.14159" upper="3.14159" velocity="0.0"/>
    </joint>
    <link name="Cube32">
        <inertial>
            <origin xyz="0.0 0.24968422939053325 0.0" rpy="0 0 0"/>
            <mass value="1" />
            <inertia ixx="100" ixy="0" ixz="0" iyy="100" iyz="0" izz="100" />
        </inertial>
        <visual>
            <origin xyz="0.0 0.24968422939053325 0.0" rpy="0 0 0"/>
            <geometry>
                <box size="0.6423303190634311 0.4993684587810665 0.27928582028762894" />
            </geometry>
            <material name="Blue">
                <color rgba="0.1 0.2 0.9 0.9"/>
            </material>
        </visual>
        <collision>
            <origin xyz="0.0 0.24968422939053325 0.0" rpy="0 0 0"/>
            <geometry>
                <box size="0.6423303190634311 0.4993684587810665 0.27928582028762894" />
            </geometry>
        </collision>
    </link>
</robot>